Workbook

Sheet 육성1 골드
H1: 20 | I1: 40 | J1: 50 | K1: 60
G2: 100 | H2: =G2*0.8 -> 80 | I2: =G2*0.6 -> 60 | J2: 50 | K2: =G2*0.4 -> 40
G3: 70 | H3: =G3*0.8 -> 56 | I3: =G3*0.6 -> 42 | J3: 35 | K3: =G3*0.4 -> 28
A4: 열1 | B4: 열2 | C4: 열3 | D4: 열4 | E4: 열5 | F4: 열6 | G4: 열7 | H4: 열8 | I4: 열9 | J4: 열10 | K4: 열11 | L4: 열12 | M4: 열13
A5: 300 | B5: 638 | C5: 389 | D5: 379048 | E5: {=INDIRECT("'[상승값.xlsx]상승'!E" & A5)} -> #REF! | F5: =E5-E3 -> #REF! | G5: 0.8 | H5: =표1[[#This Row],[열6]]*표1[[#This Row],[열7]] -> #REF! | I5: 0.7 | J5: =표1[[#This Row],[열8]]/10^7 -> #REF! | L5: 300 | O5: 300 | P5: 29771226
A6: 700 | B6: 1238 | C6: 1089 | D6: 1537782 | E6: {=INDIRECT("'[상승값.xlsx]상승'!E" & A6)} -> #REF! | F6: =E6-E5 -> #REF! | G6: 0.8 | H6: =표1[[#This Row],[열6]]*표1[[#This Row],[열7]] -> #REF! | I6: 0.7 | J6: =표1[[#This Row],[열8]]/10^7 -> #REF! | K6: 300 | L6: 700 | M6: =표1[[#This Row],[열8]]/10^7 -> #REF! | O6: 700 | P6: 3.5856041e+08
A7: 1000 | E7: {=INDIRECT("'[상승값.xlsx]상승'!E" & A7)} -> #REF! | F7: =E7-E6 -> #REF! | G7: 0.8 | H7: =표1[[#This Row],[열6]]*표1[[#This Row],[열7]] -> #REF! | I7: 0.7 | J7: =표1[[#This Row],[열8]]/10^7 -> #REF! | K7: 600 | M7: =표1[[#This Row],[열8]]/10^7 -> #REF! | O7: 1000 | P7: 7.5073497e+08
A8: 1700 | B8: 2038 | C8: 2536 | D8: 4296093 | E8: {=INDIRECT("'[상승값.xlsx]상승'!E" & A8)} -> #REF! | F8: =E8-E7 -> #REF! | G8: 0.8 | H8: =표1[[#This Row],[열6]]*표1[[#This Row],[열7]] -> #REF! | I8: 0.88 | J8: =표1[[#This Row],[열8]]/10^7 -> #REF! | K8: 1000 | L8: 1700 | M8: =표1[[#This Row],[열8]]/10^7 -> #REF! | O8: 1700 | P8: 4.4902083e+09
A9: 2000 | B9: 3038 | C9: 5286 | D9: 9693982 | E9: {=INDIRECT("'[상승값.xlsx]상승'!E" & A9)} -> #REF! | F9: =E9-E8 -> #REF! | G9: 0.8 | H9: =표1[[#This Row],[열6]]*표1[[#This Row],[열7]] -> #REF! | I9: 0.88 | J9: =표1[[#This Row],[열8]]/10^7 -> #REF! | K9: 1500 | M9: =표1[[#This Row],[열8]]/10^7 -> #REF! | O9: 2000 | P9: 3548681640
A10: 2700 | E10: {=INDIRECT("'[상승값.xlsx]상승'!E" & A10)} -> #REF! | F10: =E10-E9 -> #REF! | G10: 0.7 | H10: =표1[[#This Row],[열6]]*표1[[#This Row],[열7]] -> #REF! | I10: 0.88 | J10: =표1[[#This Row],[열8]]/10^7 -> #REF! | K10: 2000 | L10: 2700 | M10: =표1[[#This Row],[열8]]/10^7 -> #REF! | O10: 2700 | P10: 11764740015
A11: 3000 | E11: {=INDIRECT("'[상승값.xlsx]상승'!E" & A11)} -> #REF! | F11: =E11-E10 -> #REF! | G11: 0.6 | H11: =표1[[#This Row],[열6]]*표1[[#This Row],[열7]] -> #REF! | I11: 0.8 | J11: =표1[[#This Row],[열8]]/10^7 -> #REF! | K11: 2500 | L11: 3000 | M11: =표1[[#This Row],[열8]]/10^7 -> #REF! | O11: 3000 | P11: 6.3199712e+09
A12: 3700 | E12: {=INDIRECT("'[상승값.xlsx]상승'!E" & A12)} -> #REF! | F12: =E12-E11 -> #REF! | G12: 0.6 | H12: =표1[[#This Row],[열6]]*표1[[#This Row],[열7]] -> #REF! | I12: 0.8 | J12: =표1[[#This Row],[열8]]/10^7 -> #REF! | K12: 3000 | L12: 3700 | M12: =표1[[#This Row],[열8]]/10^7 -> #REF! | O12: 3700 | P12: 2.044047e+10
A13: 4000 | E13: {=INDIRECT("'[상승값.xlsx]상승'!E" & A13)} -> #REF! | F13: =E13-E12 -> #REF! | G13: 0.6 | H13: =표1[[#This Row],[열6]]*표1[[#This Row],[열7]] -> #REF! | I13: 0.8 | J13: =표1[[#This Row],[열8]]/10^7 -> #REF! | K13: 3500 | L13: 4000 | M13: =표1[[#This Row],[열8]]/10^7 -> #REF! | O13: 4000 | P13: 1.1538431e+10
A14: 4700 | E14: {=INDIRECT("'[상승값.xlsx]상승'!E" & A14)} -> #REF! | F14: =E14-E13 -> #REF! | G14: 0.6 | H14: =표1[[#This Row],[열6]]*표1[[#This Row],[열7]] -> #REF! | I14: 0.8 | J14: =표1[[#This Row],[열8]]/10^7 -> #REF! | K14: 4000 | L14: 4700 | M14: =표1[[#This Row],[열8]]/10^7 -> #REF! | O14: 4700 | P14: 3.4436876e+10
A15: 5000 | E15: {=INDIRECT("'[상승값.xlsx]상승'!E" & A15)} -> #REF! | F15: =E15-E14 -> #REF! | G15: 0.6 | H15: =표1[[#This Row],[열6]]*표1[[#This Row],[열7]] -> #REF! | I15: 0.8 | J15: =표1[[#This Row],[열8]]/10^7 -> #REF! | K15: 4500 | L15: 5000 | M15: =표1[[#This Row],[열8]]/10^7 -> #REF! | O15: 5000 | P15: 1.8316891e+10
A16: 5700 | E16: {=INDIRECT("'[상승값.xlsx]상승'!E" & A16)} -> #REF! | F16: =E16-E15 -> #REF! | G16: 0.6 | H16: =표1[[#This Row],[열6]]*표1[[#This Row],[열7]] -> #REF! | I16: 0.8 | J16: =표1[[#This Row],[열8]]/10^7 -> #REF! | K16: 5000 | L16: 5700 | M16: =표1[[#This Row],[열8]]/10^7 -> #REF! | O16: 5700 | P16: 5.2073283e+10
A17: 6000 | E17: {=INDIRECT("'[상승값.xlsx]상승'!E" & A17)} -> #REF! | F17: =E17-E16 -> #REF! | G17: 0.6 | H17: =표1[[#This Row],[열6]]*표1[[#This Row],[열7]] -> #REF! | I17: 0.8 | J17: =표1[[#This Row],[열8]]/10^7 -> #REF! | K17: 5500 | L17: 6000 | M17: =표1[[#This Row],[열8]]/10^7 -> #REF! | O17: 6000 | P17: 2.6655351e+10
A18: 6700 | E18: {=INDIRECT("'[상승값.xlsx]상승'!E" & A18)} -> #REF! | F18: =E18-E17 -> #REF! | G18: 0.55 | H18: =표1[[#This Row],[열6]]*표1[[#This Row],[열7]] -> #REF! | I18: 0.8 | J18: =표1[[#This Row],[열8]]/10^7 -> #REF! | K18: 6000 | L18: 6700 | M18: =표1[[#This Row],[열8]]/10^7 -> #REF! | O18: 6700 | P18: 6.7237215e+10
A19: 7000 | E19: {=INDIRECT("'[상승값.xlsx]상승'!E" & A19)} -> #REF! | F19: =E19-E18 -> #REF! | G19: 0.55 | H19: =표1[[#This Row],[열6]]*표1[[#This Row],[열7]] -> #REF! | I19: 0.6 | J19: =표1[[#This Row],[열8]]/10^7 -> #REF! | K19: 6500 | L19: 7000 | M19: =표1[[#This Row],[열8]]/10^7 -> #REF! | O19: 7000 | P19: 3.350766e+10
A20: 7700 | E20: {=INDIRECT("'[상승값.xlsx]상승'!E" & A20)} -> #REF! | F20: =E20-E19 -> #REF! | G20: 0.55 | H20: =표1[[#This Row],[열6]]*표1[[#This Row],[열7]] -> #REF! | I20: 0.6 | J20: =표1[[#This Row],[열8]]/10^7 -> #REF! | K20: 7000 | L20: 7700 | M20: =표1[[#This Row],[열8]]/10^7 -> #REF! | O20: 7700 | P20: 9.0077255e+10
A21: 8000 | E21: {=INDIRECT("'[상승값.xlsx]상승'!E" & A21)} -> #REF! | F21: =E21-E20 -> #REF! | G21: 0.55 | H21: =표1[[#This Row],[열6]]*표1[[#This Row],[열7]] -> #REF! | I21: 0.6 | J21: =표1[[#This Row],[열8]]/10^7 -> #REF! | K21: 7500 | L21: 8000 | M21: =표1[[#This Row],[열8]]/10^7 -> #REF! | O21: 8000 | P21: 4.4011249e+10
... A44: 19700 | E44: {=INDIRECT("'[상승값.xlsx]상승'!E" & A44)} -> #REF! | F44: =E44-E43 -> #REF! | G44: 0.43 | H44: =표1[[#This Row],[열6]]*표1[[#This Row],[열7]] -> #REF! | I44: 0.43 | J44: =표1[[#This Row],[열8]]/10^7 -> #REF! | K44: 19000 | L44: 19700 | M44: =표1[[#This Row],[열8]]/10^7 -> #REF! | O44: 19700 | P44: 4.8818113e+11
H45: =표1[[#This Row],[열6]]*표1[[#This Row],[열7]] -> 0 | I45: =표1[[#This Row],[열7]]/표1[[#This Row],[열6]] -> #DIV/0! | J45: =표1[[#This Row],[열8]]/10^7 -> 0 | K45: 19500 | M45: =표1[[#This Row],[열8]]/10^7 -> 0

Sheet 묘묙석
M2: 100 | N2: 12
B3: 0.88 | C3: ='육성1 골드'!H4*B3 -> #VALUE! | D3: 9900 | M3: =100+나무계산!O$4*나무계산!K4 -> 101 | N3: =150+나무계산!K4*나무계산!O$5 -> 152 | O3: =N$102+나무계산!O$6*나무계산!K4 -> 353 | P3: =O$102+나무계산!O$7*나무계산!K4 -> 654 | Q3: =P$102+나무계산!O$8*나무계산!K4 -> 1055 | S3: 25 | U3: =SUM(M3:M27) -> 2825
B4: 0.88 | C4: ='육성1 골드'!H5*B4 -> #REF! | D4: 12100 | M4: =100+나무계산!O$4*나무계산!K5 -> 102 | N4: =150+나무계산!K5*나무계산!O$5 -> 154 | O4: =N$102+나무계산!O$6*나무계산!K5 -> 356 | P4: =O$102+나무계산!O$7*나무계산!K5 -> 658 | Q4: =P$102+나무계산!O$8*나무계산!K5 -> 1060 | S4: 125
B5: 0.88 | C5: ='육성1 골드'!H6*B5 -> #REF! | D5: 70400 | M5: =100+나무계산!O$4*나무계산!K6 -> 103 | N5: =150+나무계산!K6*나무계산!O$5 -> 156 | O5: =N$102+나무계산!O$6*나무계산!K6 -> 359 | P5: =O$102+나무계산!O$7*나무계산!K6 -> 662 | Q5: =P$102+나무계산!O$8*나무계산!K6 -> 1065 | S5: 225
B6: 0.8 | C6: ='육성1 골드'!H7*B6 -> #REF! | D6: 96000 | M6: =100+나무계산!O$4*나무계산!K7 -> 104 | N6: =150+나무계산!K7*나무계산!O$5 -> 158 | O6: =N$102+나무계산!O$6*나무계산!K7 -> 362 | P6: =O$102+나무계산!O$7*나무계산!K7 -> 666 | Q6: =P$102+나무계산!O$8*나무계산!K7 -> 1070 | S6: 325
B7: 0.8 | C7: ='육성1 골드'!H8*B7 -> #REF! | D7: 136000 | M7: =100+나무계산!O$4*나무계산!K8 -> 105 | N7: =150+나무계산!K8*나무계산!O$5 -> 160 | O7: =N$102+나무계산!O$6*나무계산!K8 -> 365 | P7: =O$102+나무계산!O$7*나무계산!K8 -> 670 | Q7: =P$102+나무계산!O$8*나무계산!K8 -> 1075 | S7: 425
B8: 0.8 | C8: ='육성1 골드'!H9*B8 -> #REF! | D8: 184000 | M8: =100+나무계산!O$4*나무계산!K9 -> 106 | N8: =150+나무계산!K9*나무계산!O$5 -> 162 | O8: =N$102+나무계산!O$6*나무계산!K9 -> 368 | P8: =O$102+나무계산!O$7*나무계산!K9 -> 674 | Q8: =P$102+나무계산!O$8*나무계산!K9 -> 1080 | S8: 525
B9: 0.8 | C9: ='육성1 골드'!H10*B9 -> #REF! | D9: 240000 | M9: =100+나무계산!O$4*나무계산!K10 -> 107 | N9: =150+나무계산!K10*나무계산!O$5 -> 164 | O9: =N$102+나무계산!O$6*나무계산!K10 -> 371 | P9: =O$102+나무계산!O$7*나무계산!K10 -> 678 | Q9: =P$102+나무계산!O$8*나무계산!K10 -> 1085 | S9: 625
B10: 0.8 | C10: ='육성1 골드'!H11*B10 -> #REF! | D10: 304000 | M10: =100+나무계산!O$4*나무계산!K11 -> 108 | N10: =150+나무계산!K11*나무계산!O$5 -> 166 | O10: =N$102+나무계산!O$6*나무계산!K11 -> 374 | P10: =O$102+나무계산!O$7*나무계산!K11 -> 682 | Q10: =P$102+나무계산!O$8*나무계산!K11 -> 1090 | S10: 725
B11: 0.8 | C11: ='육성1 골드'!H12*B11 -> #REF! | D11: 376000 | M11: =100+나무계산!O$4*나무계산!K12 -> 109 | N11: =150+나무계산!K12*나무계산!O$5 -> 168 | O11: =N$102+나무계산!O$6*나무계산!K12 -> 377 | P11: =O$102+나무계산!O$7*나무계산!K12 -> 686 | Q11: =P$102+나무계산!O$8*나무계산!K12 -> 1095 | S11: 825
B12: 0.6 | C12: ='육성1 골드'!H13*B12 -> #REF! | D12: 342000 | M12: =100+나무계산!O$4*나무계산!K13 -> 110 | N12: =150+나무계산!K13*나무계산!O$5 -> 170 | O12: =N$102+나무계산!O$6*나무계산!K13 -> 380 | P12: =O$102+나무계산!O$7*나무계산!K13 -> 690 | Q12: =P$102+나무계산!O$8*나무계산!K13 -> 1100 | S12: 925
B13: 0.6 | C13: ='육성1 골드'!H14*B13 -> #REF! | D13: 408000 | M13: =100+나무계산!O$4*나무계산!K14 -> 111 | N13: =150+나무계산!K14*나무계산!O$5 -> 172 | O13: =N$102+나무계산!O$6*나무계산!K14 -> 383 | P13: =O$102+나무계산!O$7*나무계산!K14 -> 694 | Q13: =P$102+나무계산!O$8*나무계산!K14 -> 1105 | S13: 1025
B14: 0.6 | C14: ='육성1 골드'!H15*B14 -> #REF! | D14: 480000 | M14: =100+나무계산!O$4*나무계산!K15 -> 112 | N14: =150+나무계산!K15*나무계산!O$5 -> 174 | O14: =N$102+나무계산!O$6*나무계산!K15 -> 386 | P14: =O$102+나무계산!O$7*나무계산!K15 -> 698 | Q14: =P$102+나무계산!O$8*나무계산!K15 -> 1110 | S14: 1125
B15: 0.6 | C15: ='육성1 골드'!H16*B15 -> #REF! | D15: 558000 | M15: =100+나무계산!O$4*나무계산!K16 -> 113 | N15: =150+나무계산!K16*나무계산!O$5 -> 176 | O15: =N$102+나무계산!O$6*나무계산!K16 -> 389 | P15: =O$102+나무계산!O$7*나무계산!K16 -> 702 | Q15: =P$102+나무계산!O$8*나무계산!K16 -> 1115 | S15: 1225
... B22: 0.55 | C22: ='육성1 골드'!H23*B22 -> #REF! | D22: 1166000 | M22: =100+나무계산!O$4*나무계산!K23 -> 120 | N22: =150+나무계산!K23*나무계산!O$5 -> 190 | O22: =N$102+나무계산!O$6*나무계산!K23 -> 410 | P22: =O$102+나무계산!O$7*나무계산!K23 -> 730 | Q22: =P$102+나무계산!O$8*나무계산!K23 -> 1150 | S22: 1925
B23: 0.55 | C23: ='육성1 골드'!H24*B23 -> #REF! | D23: 1281500 | L23: 21 | M23: =100+나무계산!O$4*L23 -> 121 | N23: =150+L23*나무계산!O$5 -> 192 | O23: =N$102+나무계산!O$6*L23 -> 413 | P23: =O$102+나무계산!O$7*L23 -> 734 | Q23: =P$102+나무계산!O$8*L23 -> 1155
B24: 0.55 | C24: ='육성1 골드'!H25*B24 -> #REF! | D24: 1402500 | L24: 22 | M24: =100+나무계산!O$4*L24 -> 122 | N24: =150+L24*나무계산!O$5 -> 194 | O24: =N$102+나무계산!O$6*L24 -> 416 | P24: =O$102+나무계산!O$7*L24 -> 738 | Q24: =P$102+나무계산!O$8*L24 -> 1160
B25: 0.5 | C25: ='육성1 골드'!H26*B25 -> #REF! | D25: 1390000 | L25: 23 | M25: =100+나무계산!O$4*L25 -> 123 | N25: =150+L25*나무계산!O$5 -> 196 | O25: =N$102+나무계산!O$6*L25 -> 419 | P25: =O$102+나무계산!O$7*L25 -> 742 | Q25: =P$102+나무계산!O$8*L25 -> 1165
B26: 0.5 | C26: ='육성1 골드'!H27*B26 -> #REF! | D26: 1510000 | L26: 24 | M26: =100+나무계산!O$4*L26 -> 124 | N26: =150+L26*나무계산!O$5 -> 198 | O26: =N$102+나무계산!O$6*L26 -> 422 | P26: =O$102+나무계산!O$7*L26 -> 746 | Q26: =P$102+나무계산!O$8*L26 -> 1170
B27: 0.45 | C27: ='육성1 골드'!H28*B27 -> #REF! | D27: 1471500 | L27: 25 | M27: =100+나무계산!O$4*L27 -> 125 | N27: =150+L27*나무계산!O$5 -> 200 | O27: =N$102+나무계산!O$6*L27 -> 425 | P27: =O$102+나무계산!O$7*L27 -> 750 | Q27: =P$102+나무계산!O$8*L27 -> 1175
B28: 0.43 | C28: ='육성1 골드'!H29*B28 -> #REF! | D28: 1517900 | L28: 26 | M28: =100+나무계산!O$4*L28 -> 126 | N28: =150+L28*나무계산!O$5 -> 202 | O28: =N$102+나무계산!O$6*L28 -> 428 | P28: =O$102+나무계산!O$7*L28 -> 754 | Q28: =P$102+나무계산!O$8*L28 -> 1180
B29: 0.43 | C29: ='육성1 골드'!H30*B29 -> #REF! | D29: 1634000 | L29: 27 | M29: =100+나무계산!O$4*L29 -> 127 | N29: =150+L29*나무계산!O$5 -> 204 | O29: =N$102+나무계산!O$6*L29 -> 431 | P29: =O$102+나무계산!O$7*L29 -> 758 | Q29: =P$102+나무계산!O$8*L29 -> 1185
B30: 0.43 | C30: ='육성1 골드'!H31*B30 -> #REF! | D30: 1754400 | L30: 28 | M30: =100+나무계산!O$4*L30 -> 128 | N30: =150+L30*나무계산!O$5 -> 206 | O30: =N$102+나무계산!O$6*L30 -> 434 | P30: =O$102+나무계산!O$7*L30 -> 762 | Q30: =P$102+나무계산!O$8*L30 -> 1190
B31: 0.43 | C31: ='육성1 골드'!H32*B31 -> #REF! | D31: 1879100 | L31: 29 | M31: =100+나무계산!O$4*L31 -> 129 | N31: =150+L31*나무계산!O$5 -> 208 | O31: =N$102+나무계산!O$6*L31 -> 437 | P31: =O$102+나무계산!O$7*L31 -> 766 | Q31: =P$102+나무계산!O$8*L31 -> 1195
B32: 0.43 | C32: ='육성1 골드'!H33*B32 -> #REF! | D32: 2008100 | L32: 30 | M32: =100+나무계산!O$4*L32 -> 130 | N32: =150+L32*나무계산!O$5 -> 210 | O32: =N$102+나무계산!O$6*L32 -> 440 | P32: =O$102+나무계산!O$7*L32 -> 770 | Q32: =P$102+나무계산!O$8*L32 -> 1200
L33: 31 | M33: =100+나무계산!O$4*L33 -> 131 | N33: =150+L33*나무계산!O$5 -> 212 | O33: =N$102+나무계산!O$6*L33 -> 443 | P33: =O$102+나무계산!O$7*L33 -> 774 | Q33: =P$102+나무계산!O$8*L33 -> 1205
L34: 32 | M34: =100+나무계산!O$4*L34 -> 132 | N34: =150+L34*나무계산!O$5 -> 214 | O34: =N$102+나무계산!O$6*L34 -> 446 | P34: =O$102+나무계산!O$7*L34 -> 778 | Q34: =P$102+나무계산!O$8*L34 -> 1210
L35: 33 | M35: =100+나무계산!O$4*L35 -> 133 | N35: =150+L35*나무계산!O$5 -> 216 | O35: =N$102+나무계산!O$6*L35 -> 449 | P35: =O$102+나무계산!O$7*L35 -> 782 | Q35: =P$102+나무계산!O$8*L35 -> 1215
F36: 육성 | L36: 34 | M36: =100+나무계산!O$4*L36 -> 134 | N36: =150+L36*나무계산!O$5 -> 218 | O36: =N$102+나무계산!O$6*L36 -> 452 | P36: =O$102+나무계산!O$7*L36 -> 786 | Q36: =P$102+나무계산!O$8*L36 -> 1220
L37: 35 | M37: =100+나무계산!O$4*L37 -> 135 | N37: =150+L37*나무계산!O$5 -> 220 | O37: =N$102+나무계산!O$6*L37 -> 455 | P37: =O$102+나무계산!O$7*L37 -> 790 | Q37: =P$102+나무계산!O$8*L37 -> 1225
L38: 36 | M38: =100+나무계산!O$4*L38 -> 136 | N38: =150+L38*나무계산!O$5 -> 222 | O38: =N$102+나무계산!O$6*L38 -> 458 | P38: =O$102+나무계산!O$7*L38 -> 794 | Q38: =P$102+나무계산!O$8*L38 -> 1230
B39: 700 | C39: 3.5856041e+08 | E39: =C39/(10^5) -> 3585.6041 | F39: =E39/1000 -> 3.5856041 | G39: 5 | L39: 37 | M39: =100+나무계산!O$4*L39 -> 137 | N39: =150+L39*나무계산!O$5 -> 224 | O39: =N$102+나무계산!O$6*L39 -> 461 | P39: =O$102+나무계산!O$7*L39 -> 798 | Q39: =P$102+나무계산!O$8*L39 -> 1235
B40: 1700 | C40: 4.4902083e+09 | E40: =C40/(10^5) -> 44902.083 | F40: =E40/1000 -> 44.902083 | G40: 5 | L40: 38 | M40: =100+나무계산!O$4*L40 -> 138 | N40: =150+L40*나무계산!O$5 -> 226 | O40: =N$102+나무계산!O$6*L40 -> 464 | P40: =O$102+나무계산!O$7*L40 -> 802 | Q40: =P$102+나무계산!O$8*L40 -> 1240
B41: 2700 | C41: 11764740015 | E41: =C41/(10^7) -> 1176.474 | F41: =E41/1000 -> 1.176474 | L41: 39 | M41: =100+나무계산!O$4*L41 -> 139 | N41: =150+L41*나무계산!O$5 -> 228 | O41: =N$102+나무계산!O$6*L41 -> 467 | P41: =O$102+나무계산!O$7*L41 -> 806 | Q41: =P$102+나무계산!O$8*L41 -> 1245
B42: 3700 | C42: 2.044047e+10 | E42: =C42/(10^7) -> 2044.047 | F42: =E42/1000 -> 2.044047 | L42: 40 | M42: =100+나무계산!O$4*L42 -> 140 | N42: =150+L42*나무계산!O$5 -> 230 | O42: =N$102+나무계산!O$6*L42 -> 470 | P42: =O$102+나무계산!O$7*L42 -> 810 | Q42: =P$102+나무계산!O$8*L42 -> 1250
B43: 4700 | C43: 3.4436876e+10 | E43: =C43/(10^7) -> 3443.6876 | F43: =E43/1000 -> 3.4436876 | L43: 41 | M43: =100+나무계산!O$4*L43 -> 141 | N43: =150+L43*나무계산!O$5 -> 232 | O43: =N$102+나무계산!O$6*L43 -> 473 | P43: =O$102+나무계산!O$7*L43 -> 814 | Q43: =P$102+나무계산!O$8*L43 -> 1255
B44: 5700 | C44: 5.2073283e+10 | E44: =C44/(10^7) -> 5207.3283 | F44: =E44/1000 -> 5.2073283 | L44: 42 | M44: =100+나무계산!O$4*L44 -> 142 | N44: =150+L44*나무계산!O$5 -> 234 | O44: =N$102+나무계산!O$6*L44 -> 476 | P44: =O$102+나무계산!O$7*L44 -> 818 | Q44: =P$102+나무계산!O$8*L44 -> 1260
B45: 6700 | C45: 6.7237215e+10 | E45: =C45/(10^7) -> 6723.7215 | F45: =E45/1000 -> 6.7237215 | L45: 43 | M45: =100+나무계산!O$4*L45 -> 143 | N45: =150+L45*나무계산!O$5 -> 236 | O45: =N$102+나무계산!O$6*L45 -> 479 | P45: =O$102+나무계산!O$7*L45 -> 822 | Q45: =P$102+나무계산!O$8*L45 -> 1265
B46: 7700 | C46: 9.0077255e+10 | E46: =C46/(10^7) -> 9007.7255 | F46: =E46/1000 -> 9.0077255 | L46: 44 | M46: =100+나무계산!O$4*L46 -> 144 | N46: =150+L46*나무계산!O$5 -> 238 | O46: =N$102+나무계산!O$6*L46 -> 482 | P46: =O$102+나무계산!O$7*L46 -> 826 | Q46: =P$102+나무계산!O$8*L46 -> 1270
B47: 8700 | C47: 1.1625396e+11 | E47: =C47/(10^7) -> 11625.396 | F47: =E47/1000 -> 11.625396 | L47: 45 | M47: =100+나무계산!O$4*L47 -> 145 | N47: =150+L47*나무계산!O$5 -> 240 | O47: =N$102+나무계산!O$6*L47 -> 485 | P47: =O$102+나무계산!O$7*L47 -> 830 | Q47: =P$102+나무계산!O$8*L47 -> 1275
...

Sheet 나무계산
T1: 나무계산 | X1: =S1*V1*0.6 -> 0 | AA1: 100 | AB1: =AA1*100 -> 10000
X2: =S2*V2*0.6 -> 0 | AA2: 250 | AB2: =AA2*200 -> 50000
M3: 50 | N3: 100 | P3: 시작 | Q3: 중간값 | R3: 끝값 | T3: 시작 | U3: 중간 | X3: =S3*V3*0.6 -> 0 | Z3: =Z5/200 -> 114
A4: 1 | B4: 씨앗 | C4: 25 | D4: 50 | E4: 75 | I4: 0 | K4: 1 | L4: 0 | M4: 25 | N4: 50 | O4: 1 | P4: 100 | Q4: =P4+M4*$K4 -> 125 | R4: =$P$4+N4*$K4 -> 150 | T4: =25*(P4+Q4)/2*4 -> 11250 | U4: =25*(R4+Q4)/2*4 -> 13750 | V4: =U4+T4 -> 25000 | W4: 0.95 | X4: 6412.5 | Y4: 7837.5 | Z4: =T4*W4*0.6 -> 6412.5 | AA4: =U4*W4*0.6 -> 7837.5 | AC4: =V4*W4*0.6 -> 14250 | AE4: 1 | AF4: 12000 | AG4: 1 | AH4: 5400 | AI4: 1
A5: 2 | B5: 뿌리 | C5: 125 | D5: 150 | E5: 125 | I5: 25 | K5: 2 | L5: 50 | M5: 100 | N5: 150 | O5: 2 | P5: =R4 -> 150 | Q5: =P5+(M5-L5)*O5 -> 250 | R5: =Q5+(N5-M5)*O5 -> 350 | T5: =50*(P5+Q5)/2*4 -> 40000 | U5: =50*(R5+Q5)/2*4 -> 60000 | V5: =U5+T5 -> 100000 | W5: 0.95 | X5: 22800 | Y5: 34200 | Z5: =T5*W5*0.6 -> 22800 | AA5: =U5*W5*0.6 -> 34200 | AC5: =V5*W5*0.6 -> 57000 | AE5: 200 | AF5: 48000 | AG5: 200 | AH5: 6600 | AI5: 2
A6: 3 | B6: 새싹 | C6: 225 | D6: 250 | E6: 175 | I6: 50 | K6: 3 | L6: 150 | M6: 200 | N6: 250 | O6: 3 | P6: =R5 -> 350 | Q6: =P6+(M6-L6)*O6 -> 500 | R6: =Q6+(N6-M6)*O6 -> 650 | T6: =50*(P6+Q6)/2*4 -> 85000 | U6: =50*(R6+Q6)/2*4 -> 115000 | V6: =U6+T6 -> 200000 | W6: 0.9 | X6: 45900 | Y6: 62100 | Z6: =T6*W6*0.6 -> 45900 | AA6: =U6*W6*0.6 -> 62100 | AC6: =V6*W6*0.6 -> 108000 | AE6: 600 | AF6: 84000 | AG6: 400 | AH6: 19200 | AI6: 3
A7: 4 | B7: 잎새 | C7: 325 | D7: 350 | E7: 225 | I7: 100 | K7: 4 | L7: 250 | M7: 300 | N7: 350 | O7: 4 | P7: =R6 -> 650 | Q7: =P7+(M7-L7)*O7 -> 850 | R7: =Q7+(N7-M7)*O7 -> 1050 | T7: =50*(P7+Q7)/2*4 -> 150000 | U7: =50*(R7+Q7)/2*4 -> 190000 | V7: =U7+T7 -> 340000 | W7: 0.9 | X7: 81000 | Y7: 102600 | Z7: =T7*W7*0.6 -> 81000 | AA7: =U7*W7*0.6 -> 102600 | AC7: =V7*W7*0.6 -> 183600 | AE7: 1000 | AF7: 142800 | AG7: 600 | AH7: 28800 | AI7: 4
A8: 5 | B8: 가지 | C8: 425 | D8: 450 | E8: 275 | I8: 150 | K8: 5 | L8: 350 | M8: 400 | N8: 450 | O8: 5 | P8: =R7 -> 1050 | Q8: =P8+(M8-L8)*O8 -> 1300 | R8: =Q8+(N8-M8)*O8 -> 1550 | T8: =50*(P8+Q8)/2*4 -> 235000 | U8: =50*(R8+Q8)/2*4 -> 285000 | V8: =U8+T8 -> 520000 | W8: 0.85 | X8: 119850 | Y8: 145350 | Z8: =T8*W8*0.6 -> 119850 | AA8: =U8*W8*0.6 -> 145350 | AC8: =V8*W8*0.6 -> 265200 | AE8: 1400 | AF8: 187200 | AG8: 800 | AH8: 35700 | AI8: 5
A9: 6 | B9: 묘목 | C9: 525 | D9: 550 | E9: 325 | I9: 200 | K9: 6 | L9: 450 | M9: 500 | N9: 550 | O9: 6 | P9: =R8 -> 1550 | Q9: =P9+(M9-L9)*O9 -> 1850 | R9: =Q9+(N9-M9)*O9 -> 2150 | T9: =50*(P9+Q9)/2*4 -> 340000 | U9: =50*(R9+Q9)/2*4 -> 400000 | V9: =U9+T9 -> 740000 | W9: 0.8 | X9: 163200 | Y9: 192000 | Z9: =T9*W9*0.6 -> 163200 | AA9: =U9*W9*0.6 -> 192000 | AC9: =V9*W9*0.6 -> 355200 | AE9: 1800 | AF9: 266400 | AG9: 1000 | AH9: 48300 | AI9: 6
A10: 7 | B10: 견목 | C10: 625 | D10: 650 | E10: 375 | I10: 250 | K10: 7 | L10: 550 | M10: 600 | N10: 650 | O10: 7 | P10: =R9 -> 2150 | Q10: =P10+(M10-L10)*O10 -> 2500 | R10: =Q10+(N10-M10)*O10 -> 2850 | T10: =50*(P10+Q10)/2*4 -> 465000 | U10: =50*(R10+Q10)/2*4 -> 535000 | V10: =U10+T10 -> 1000000 | W10: 0.8 | X10: 223200 | Y10: 256800 | Z10: =T10*W10*0.6 -> 223200 | AA10: =U10*W10*0.6 -> 256800 | AC10: =V10*W10*0.6 -> 480000 | AE10: 2200 | AF10: 360000 | AG10: 1200 | AH10: 63000 | AI10: 7
A11: 8 | B11: 성목 | C11: 725 | D11: 750 | E11: 425 | I11: 300 | K11: 8 | L11: 650 | M11: 700 | N11: 750 | O11: 8 | P11: =R10 -> 2850 | Q11: =P11+(M11-L11)*O11 -> 3250 | R11: =Q11+(N11-M11)*O11 -> 3650 | T11: =50*(P11+Q11)/2*4 -> 610000 | U11: =50*(R11+Q11)/2*4 -> 690000 | V11: =U11+T11 -> 1300000 | W11: 0.75 | X11: 274500 | Y11: 310500 | Z11: =T11*W11*0.6 -> 274500 | AA11: =U11*W11*0.6 -> 310500 | AC11: =V11*W11*0.6 -> 585000 | AE11: 2600 | AF11: 468000 | AG11: 1400 | AH11: 79800 | AI11: 8
A12: 9 | B12: 거목 | C12: 825 | D12: 850 | E12: 475 | I12: 350 | K12: 9 | L12: 750 | M12: 800 | N12: 850 | O12: 9 | P12: =R11 -> 3650 | Q12: =P12+(M12-L12)*O12 -> 4100 | R12: =Q12+(N12-M12)*O12 -> 4550 | T12: =50*(P12+Q12)/2*4 -> 775000 | U12: =50*(R12+Q12)/2*4 -> 865000 | V12: =U12+T12 -> 1640000 | W12: 0.7 | X12: 325500 | Y12: 363300 | Z12: =T12*W12*0.6 -> 325500 | AA12: =U12*W12*0.6 -> 363300 | AC12: =V12*W12*0.6 -> 688800 | AE12: 3000 | AF12: 590400 | AG12: 1600 | AH12: 84600 | AI12: 9
A13: 10 | B13: 신목 | C13: 925 | D13: 950 | E13: 525 | I13: 400 | K13: 10 | L13: 850 | M13: 900 | N13: 950 | O13: 10 | P13: =R12 -> 4550 | Q13: =P13+(M13-L13)*O13 -> 5050 | R13: =Q13+(N13-M13)*O13 -> 5550 | T13: =50*(P13+Q13)/2*4 -> 960000 | U13: =50*(R13+Q13)/2*4 -> 1060000 | V13: =U13+T13 -> 2020000 | W13: 0.7 | X13: 403200 | Y13: 445200 | Z13: =T13*W13*0.6 -> 403200 | AA13: =U13*W13*0.6 -> 445200 | AC13: =V13*W13*0.6 -> 848400 | AE13: 3400 | AF13: 606000 | AG13: 1800 | AH13: 102600 | AI13: 10
A14: 11 | B14: 영목 | C14: 1025 | D14: 1050 | E14: 575 | I14: 450 | K14: 11 | L14: 950 | M14: 1000 | N14: 1050 | O14: 11 | P14: =R13 -> 5550 | Q14: =P14+(M14-L14)*O14 -> 6100 | R14: =Q14+(N14-M14)*O14 -> 6650 | T14: =50*(P14+Q14)/2*4 -> 1165000 | U14: =50*(R14+Q14)/2*4 -> 1275000 | V14: =U14+T14 -> 2440000 | W14: 0.65 | X14: 454350 | Y14: 497250 | Z14: =T14*W14*0.6 -> 454350 | AA14: =U14*W14*0.6 -> 497250 | AC14: =V14*W14*0.6 -> 951600 | AE14: 3800 | AF14: 732000 | AG14: 2000 | AH14: 122400 | AI14: 11
A15: 12 | B15: 천목 | C15: 1125 | D15: 1150 | E15: 625 | I15: 500 | K15: 12 | L15: 1050 | M15: 1100 | N15: 1150 | O15: 12 | P15: =R14 -> 6650 | Q15: =P15+(M15-L15)*O15 -> 7250 | R15: =Q15+(N15-M15)*O15 -> 7850 | T15: =50*(P15+Q15)/2*4 -> 1390000 | U15: =50*(R15+Q15)/2*4 -> 1510000 | V15: =U15+T15 -> 2900000 | W15: 0.65 | X15: 542100 | Y15: 588900 | Z15: =T15*W15*0.6 -> 542100 | AA15: =U15*W15*0.6 -> 588900 | AC15: =V15*W15*0.6 -> 1131000 | AE15: 4200 | AF15: 870000 | AG15: 2200 | AH15: 144000 | AI15: 12
A16: 13 | B16: 태초목 | C16: 1225 | D16: 1250 | E16: 675 | I16: 550 | K16: 13 | L16: 1150 | M16: 1200 | N16: 1250 | O16: 13 | P16: =R15 -> 7850 | Q16: =P16+(M16-L16)*O16 -> 8500 | R16: =Q16+(N16-M16)*O16 -> 9150 | T16: =50*(P16+Q16)/2*4 -> 1635000 | U16: =50*(R16+Q16)/2*4 -> 1765000 | V16: =U16+T16 -> 3400000 | W16: 0.6 | X16: 588600 | Y16: 635400 | Z16: =T16*W16*0.6 -> 588600 | AA16: =U16*W16*0.6 -> 635400 | AC16: =V16*W16*0.6 -> 1224000 | AE16: 4600 | AF16: 1020000 | AG16: 2400 | AH16: 167400 | AI16: 13
... A23: 20 | B23: 영겁수 | C23: 1925 | D23: 1950 | E23: 1025 | I23: 900 | K23: 20 | L23: 1850 | M23: 1900 | N23: 1950 | O23: 20 | P23: =R22 -> 19050 | Q23: =P23+(M23-L23)*O23 -> 20050 | R23: =Q23+(N23-M23)*O23 -> 21050 | T23: =50*(P23+Q23)/2*4 -> 3910000 | U23: =50*(R23+Q23)/2*4 -> 4110000 | V23: =U23+T23 -> 8020000 | W23: 0.5 | X23: 1173000 | Y23: 1233000 | Z23: =T23*W23*0.6 -> 1173000 | AA23: =U23*W23*0.6 -> 1233000 | AC23: =V23*W23*0.6 -> 2406000 | AE23: 7400 | AF23: 2406000 | AG23: 3800 | AH23: 318000 | AI23: 20
I24: 950 | L24: 1950 | M24: 2000 | N24: 2050 | O24: 21 | P24: =R23 -> 21050 | Q24: =P24+(M24-L24)*O24 -> 22100 | R24: =Q24+(N24-M24)*O24 -> 23150 | T24: =50*(P24+Q24)/2*4 -> 4315000 | U24: =50*(R24+Q24)/2*4 -> 4525000 | V24: =U24+T24 -> 8840000 | W24: 1.5 | X24: 3883500 | Y24: 4072500 | Z24: =T24*W24*0.6 -> 3883500 | AA24: =U24*W24*0.6 -> 4072500 | AC24: =V24*W24*0.6 -> 7956000 | AG24: 4000 | AH24: 349500 | AI24: 21
I25: 1000 | L25: 2050 | M25: 2100 | N25: 2150 | O25: 22 | P25: =R24 -> 23150 | Q25: =P25+(M25-L25)*O25 -> 24250 | R25: =Q25+(N25-M25)*O25 -> 25350 | T25: =50*(P25+Q25)/2*4 -> 4740000 | U25: =50*(R25+Q25)/2*4 -> 4960000 | V25: =U25+T25 -> 9700000 | W25: 2.5 | X25: 7110000 | Y25: 7440000 | Z25: =T25*W25*0.6 -> 7110000 | AA25: =U25*W25*0.6 -> 7440000 | AC25: =V25*W25*0.6 -> 14550000 | AG25: 4200 | AH25: 382500 | AI25: 22
I26: 1050 | L26: 2150 | M26: 2200 | N26: 2250 | O26: 23 | P26: =R25 -> 25350 | Q26: =P26+(M26-L26)*O26 -> 26500 | R26: =Q26+(N26-M26)*O26 -> 27650 | T26: =50*(P26+Q26)/2*4 -> 5185000 | U26: =50*(R26+Q26)/2*4 -> 5415000 | V26: =U26+T26 -> 10600000 | W26: 3.5 | X26: 10888500 | Y26: 11371500 | Z26: =T26*W26*0.6 -> 10888500 | AA26: =U26*W26*0.6 -> 11371500 | AC26: =V26*W26*0.6 -> 22260000 | AG26: 4400 | AH26: 417000 | AI26: 23
I27: 1100 | L27: 2250 | M27: 2300 | N27: 2350 | O27: 24 | P27: =R26 -> 27650 | Q27: =P27+(M27-L27)*O27 -> 28850 | R27: =Q27+(N27-M27)*O27 -> 30050 | T27: =50*(P27+Q27)/2*4 -> 5650000 | U27: =50*(R27+Q27)/2*4 -> 5890000 | V27: =U27+T27 -> 11540000 | W27: 4.5 | X27: 15255000 | Y27: 15903000 | Z27: =T27*W27*0.6 -> 15255000 | AA27: =U27*W27*0.6 -> 15903000 | AC27: =V27*W27*0.6 -> 31158000 | AG27: 4600 | AH27: 453000 | AI27: 24
I28: 1150 | L28: 2350 | M28: 2400 | N28: 2450 | O28: 25 | P28: =R27 -> 30050 | Q28: =P28+(M28-L28)*O28 -> 31300 | R28: =Q28+(N28-M28)*O28 -> 32550 | S28: 185 | T28: =50*(P28+Q28)/2*4 -> 6135000 | U28: =50*(R28+Q28)/2*4 -> 6385000 | V28: =U28+T28 -> 12520000 | W28: 5.5 | X28: 20245500 | Y28: 21070500 | Z28: =T28*W28*0.6 -> 20245500 | AA28: =U28*W28*0.6 -> 21070500 | AC28: =V28*W28*0.6 -> 41316000 | AG28: 4800 | AH28: 490500 | AI28: 25
I29: 1200 | L29: 2450 | M29: 2500 | N29: 2550 | O29: 26 | P29: =R28 -> 32550 | Q29: =P29+(M29-L29)*O29 -> 33850 | R29: =Q29+(N29-M29)*O29 -> 35150 | S29: 150 | T29: =50*(P29+Q29)/2*4 -> 6640000 | U29: =50*(R29+Q29)/2*4 -> 6900000 | V29: =U29+T29 -> 13540000 | W29: 6.5 | X29: 25896000 | Y29: 26910000 | Z29: =T29*W29*0.6 -> 25896000 | AA29: =U29*W29*0.6 -> 26910000 | AC29: =V29*W29*0.6 -> 52806000 | AG29: 5000 | AH29: 529500 | AI29: 26
I30: 1250 | L30: 2550 | M30: 2600 | N30: 2650 | O30: 27 | P30: =R29 -> 35150 | Q30: =P30+(M30-L30)*O30 -> 36500 | R30: =Q30+(N30-M30)*O30 -> 37850 | S30: =S28-S29 -> 35 | T30: =50*(P30+Q30)/2*4 -> 7165000 | U30: =50*(R30+Q30)/2*4 -> 7435000 | V30: =U30+T30 -> 14600000 | W30: 7.5 | X30: 32242500 | Y30: 33457500 | Z30: =T30*W30*0.6 -> 32242500 | AA30: =U30*W30*0.6 -> 33457500 | AC30: =V30*W30*0.6 -> 65700000 | AG30: 5200 | AH30: 570000 | AI30: 27
I31: 1300 | L31: 2650 | M31: 2700 | N31: 2750 | O31: 28 | P31: =R30 -> 37850 | Q31: =P31+(M31-L31)*O31 -> 39250 | R31: =Q31+(N31-M31)*O31 -> 40650 | T31: =50*(P31+Q31)/2*4 -> 7710000 | U31: =50*(R31+Q31)/2*4 -> 7990000 | V31: =U31+T31 -> 15700000 | W31: 8.5 | X31: 39321000 | Y31: 40749000 | Z31: =T31*W31*0.6 -> 39321000 | AA31: =U31*W31*0.6 -> 40749000 | AC31: =V31*W31*0.6 -> 80070000 | AG31: 5400 | AH31: 612000 | AI31: 28
I32: 1350 | L32: 2750 | M32: 2800 | N32: 2850 | O32: 29 | P32: =R31 -> 40650 | Q32: =P32+(M32-L32)*O32 -> 42100 | R32: =Q32+(N32-M32)*O32 -> 43550 | T32: =50*(P32+Q32)/2*4 -> 8275000 | U32: =50*(R32+Q32)/2*4 -> 8565000 | V32: =U32+T32 -> 16840000 | W32: 9.5 | X32: 47167500 | Y32: 48820500 | Z32: =T32*W32*0.6 -> 47167500 | AA32: =U32*W32*0.6 -> 48820500 | AC32: =V32*W32*0.6 -> 95988000 | AG32: 5600 | AH32: 655500 | AI32: 29
I33: 1400 | L33: 2850 | M33: 2900 | N33: 2950 | O33: 30 | P33: =R32 -> 43550 | Q33: =P33+(M33-L33)*O33 -> 45050 | R33: =Q33+(N33-M33)*O33 -> 46550 | T33: =50*(P33+Q33)/2*4 -> 8860000 | U33: =50*(R33+Q33)/2*4 -> 9160000 | V33: =U33+T33 -> 18020000 | W33: 10.5 | X33: 55818000 | Y33: 57708000 | Z33: =T33*W33*0.6 -> 55818000 | AA33: =U33*W33*0.6 -> 57708000 | AC33: =V33*W33*0.6 -> 113526000 | AG33: 5800 | AH33: 700500 | AI33: 30
I34: 1450 | L34: 2950 | M34: 3000 | N34: 3050 | O34: 31 | P34: =R33 -> 46550 | Q34: =P34+(M34-L34)*O34 -> 48100 | R34: =Q34+(N34-M34)*O34 -> 49650 | T34: =50*(P34+Q34)/2*4 -> 9465000 | U34: =50*(R34+Q34)/2*4 -> 9775000 | V34: =U34+T34 -> 19240000 | W34: 11.5 | X34: 65308500 | Y34: 67447500 | Z34: =T34*W34*0.6 -> 65308500 | AA34: =U34*W34*0.6 -> 67447500 | AC34: =V34*W34*0.6 -> 132756000 | AG34: 6000 | AH34: 747000 | AI34: 31
I35: 1500 | L35: 3050 | M35: 3100 | N35: 3150 | O35: 32 | P35: =R34 -> 49650 | Q35: =P35+(M35-L35)*O35 -> 51250 | R35: =Q35+(N35-M35)*O35 -> 52850 | T35: =50*(P35+Q35)/2*4 -> 10090000 | U35: =50*(R35+Q35)/2*4 -> 10410000 | V35: =U35+T35 -> 20500000 | W35: 12.5 | X35: 75675000 | Y35: 78075000 | Z35: =T35*W35*0.6 -> 75675000 | AA35: =U35*W35*0.6 -> 78075000 | AC35: =V35*W35*0.6 -> 153750000 | AG35: 6200 | AH35: 795000 | AI35: 32
I36: 1550 | L36: 3150 | M36: 3200 | N36: 3250 | O36: 33 | P36: =R35 -> 52850 | Q36: =P36+(M36-L36)*O36 -> 54500 | R36: =Q36+(N36-M36)*O36 -> 56150 | T36: =50*(P36+Q36)/2*4 -> 10735000 | U36: =50*(R36+Q36)/2*4 -> 11065000 | V36: =U36+T36 -> 21800000 | W36: 13.5 | X36: 86953500 | Y36: 89626500 | Z36: =T36*W36*0.6 -> 86953500 | AA36: =U36*W36*0.6 -> 89626500 | AC36: =V36*W36*0.6 -> 176580000 | AG36: 6400 | AH36: 844500 | AI36: 33
I37: 1600 | L37: 3250 | M37: 3300 | N37: 3350 | O37: 34 | P37: =R36 -> 56150 | Q37: =P37+(M37-L37)*O37 -> 57850 | R37: =Q37+(N37-M37)*O37 -> 59550 | T37: =50*(P37+Q37)/2*4 -> 11400000 | U37: =50*(R37+Q37)/2*4 -> 11740000 | V37: =U37+T37 -> 23140000 | W37: 14.5 | X37: 99180000 | Y37: 102138000 | Z37: =T37*W37*0.6 -> 99180000 | AA37: =U37*W37*0.6 -> 102138000 | AC37: =V37*W37*0.6 -> 201318000 | AG37: 6600 | AH37: 895500 | AI37: 34
I38: 1650 | L38: 3350 | M38: 3400 | N38: 3450 | O38: 35 | P38: =R37 -> 59550 | Q38: =P38+(M38-L38)*O38 -> 61300 | R38: =Q38+(N38-M38)*O38 -> 63050 | T38: =50*(P38+Q38)/2*4 -> 12085000 | U38: =50*(R38+Q38)/2*4 -> 12435000 | V38: =U38+T38 -> 24520000 | W38: 15.5 | X38: 112390500 | Y38: 115645500 | Z38: =T38*W38*0.6 -> 112390500 | AA38: =U38*W38*0.6 -> 115645500 | AC38: =V38*W38*0.6 -> 228036000 | AG38: 6800 | AH38: 948000 | AI38: 35
I39: 1700 | L39: 3450 | M39: 3500 | N39: 3550 | O39: 36 | P39: =R38 -> 63050 | Q39: =P39+(M39-L39)*O39 -> 64850 | R39: =Q39+(N39-M39)*O39 -> 66650 | T39: =50*(P39+Q39)/2*4 -> 12790000 | U39: =50*(R39+Q39)/2*4 -> 13150000 | V39: =U39+T39 -> 25940000 | W39: 16.5 | X39: 130185000 | Y39: 130185000 | Z39: =U39*W39*0.6 -> 130185000 | AA39: =U39*W39*0.6 -> 130185000 | AB39: =V39*W39*0.6 -> 256806000 | AF39: 7000 | AG39: 1002000 | AH39: 36
I40: 1750 | L40: 3550 | M40: 3600 | N40: 3650 | O40: 37 | P40: =R39 -> 66650 | Q40: =P40+(M40-L40)*O40 -> 68500 | R40: =Q40+(N40-M40)*O40 -> 70350 | T40: =50*(P40+Q40)/2*4 -> 13515000 | U40: =50*(R40+Q40)/2*4 -> 13885000 | V40: =U40+T40 -> 27400000 | W40: 17.5 | X40: 145792500 | Y40: 145792500 | Z40: =U40*W40*0.6 -> 145792500 | AA40: =U40*W40*0.6 -> 145792500 | AB40: =V40*W40*0.6 -> 287700000 | AF40: 7200 | AG40: 1057500 | AH40: 37
I41: 1800 | L41: 3650 | M41: 3700 | N41: 3750 | O41: 38 | P41: =R40 -> 70350 | Q41: =P41+(M41-L41)*O41 -> 72250 | R41: =Q41+(N41-M41)*O41 -> 74150 | T41: =50*(P41+Q41)/2*4 -> 14260000 | U41: =50*(R41+Q41)/2*4 -> 14640000 | V41: =U41+T41 -> 28900000 | W41: 18.5 | X41: 162504000 | Y41: 162504000 | Z41: =U41*W41*0.6 -> 162504000 | AA41: =U41*W41*0.6 -> 162504000 | AB41: =V41*W41*0.6 -> 320790000 | AF41: 7400 | AG41: 1114500 | AH41: 38
O42: 39 | W42: 0.43 | AF42: 7600 | AG42: 1173000 | AH42: 39
O43: 40 | W43: 0.43 | AF43: 7800 | AG43: 1233000 | AH43: 40

Sheet Sheet2
B3: 5400 | F3: 7837.5 | I3: 6412.5 | K3: 6412.5 | L3: 7837.5
B4: 6600 | F4: 8550 | I4: 7837.5 | K4: 7837.5
B5: 19200 | F5: 22800 | I5: 22800 | K5: 22800 | L5: 34200
B6: 28800 | F6: 34200 | I6: 34200 | K6: 34200
B7: 35700 | F7: 45900 | I7: 45900 | K7: 45900 | L7: 62100
B8: 48300 | F8: 62100 | I8: 62100 | K8: 62100
B9: 63000 | F9: 81000 | I9: 81000 | K9: 81000 | L9: 102600
B10: 79800 | F10: 102600 | I10: 102600 | K10: 102600
B11: 84600 | F11: 119850 | I11: 119850 | K11: 119850 | L11: 145350
B12: 102600 | F12: 145350 | I12: 145350 | K12: 145350
B13: 122400 | F13: 173400 | I13: 173400 | K13: 163200 | L13: 192000
B14: 144000 | F14: 204000 | I14: 204000 | K14: 192000
B15: 167400 | F15: 230175 | I15: 230175 | K15: 223200 | L15: 256800
B16: 192600 | F16: 264825 | I16: 264825 | K16: 256800
B17: 219600 | F17: 294630 | I17: 294630 | K17: 274500 | L17: 310500
B18: 248400 | F18: 333270 | I18: 333270 | K18: 310500
B19: 279000 | F19: 365025 | I19: 365025 | K19: 325500 | L19: 363300
B20: 288000 | F20: 407415 | I20: 407415 | K20: 363300
B21: 311400 | F21: 440640 | I21: 440640 | K21: 403200 | L21: 445200
B22: 318000 | F22: 486540 | I22: 486540 | K22: 445200
B23: 349500 | F23: 520755 | I23: 520755 | K23: 454350 | L23: 497250
B24: 382500 | F24: 569925 | I24: 569925 | K24: 497250
B25: 417000 | F25: 604650 | I25: 604650 | K25: 542100 | L25: 588900
B26: 453000 | F26: 656850 | I26: 656850 | K26: 588600 | L26: 635400
B27: 490500 | F27: 691605 | I27: 691605 | K27: 588900
B28: 529500 | F28: 746595 | I28: 746595 | K28: 635400
B29: 570000 | F29: 780900 | I29: 780900 | K29: 684000 | L29: 734400
B30: 612000 | F30: 838440 | I30: 838440 | K30: 734400
B31: 655500 | F31: 871815 | I31: 871815 | K31: 786600 | L31: 840600
B32: 700500 | F32: 931665 | I32: 931665 | K32: 840600
B33: 747000 | F33: 963630 | I33: 963630 | K33: 896400 | L33: 954000
B34: 795000 | F34: 1025550 | I34: 1025550 | K34: 948000 | L34: 1002000
B35: 844500 | F35: 1055625 | I35: 1055625 | K35: 954000
B36: 895500 | F36: 1119375 | I36: 1119375 | K36: 1002000
B37: 948000 | F37: 1147080 | I37: 1147080 | K37: 1013400 | L37: 1074600
B38: 1002000 | F38: 1212420 | I38: 1212420 | K38: 1057500 | L38: 1114500
B39: 1057500 | F39: 1237275 | I39: 1237275 | K39: 1074600
B40: 1114500 | F40: 1303965 | I40: 1303965 | K40: 1114500
B41: 1173000 | F41: 1325490 | I41: 1325490 | K41: 1173000 | L41: 1233000
B42: 1233000 | F42: 1393290 | I42: 1393290 | K42: 1233000

Sheet 회심타절멸타 골드
A1: ID | B1: 스탯이름 | C1: 고정값 | D1: 고정값조정 | E1: 상승값 | F1: 최대값 | G1: 예측(사용X) | H1: 누적금액 | J1: 금화감소후 | N1: 회심타
A2: 1 | B2: 공격력 | C2: 1000000000 | D2: 1 | E2: 113608 | F2: 0 | G2: 52C_4만육성 | O2: 진행율 | P2: 0.2 | Q2: 0.4 | R2: 0.6 | S2: 0.8 | T2: 1
A3: 2 | B3: 생명력 | C3: 1000000000 | D3: 1 | E3: 113608 | F3: 0 | G3: 52C_4만육성 | N3: 공격력 | O3: 1000 | P3: =$O3*P$2 -> 200 | Q3: =$O3*Q$2 -> 400 | R3: =$O3*R$2 -> 600 | S3: =$O3*S$2 -> 800 | T3: =$O3*T$2 -> 1000
A4: 3 | B4: 회심타확률 | C4: 1500000000 | D4: 1 | E4: 250501608 | F4: 1000 | G4: 51C | H4: =1000/2*(C4+999*E4) -> 125875553196000 | I4: 125c | J4: 62c | P4: =$D$72+P3*$F$72 -> 51600321600 | Q4: =$D$72+Q3*$F$72 -> 101700643200 | R4: =$D$72+R3*$F$72 -> 151800964800 | S4: =$D$72+S3*$F$72 -> 201901286400 | T4: =$D$72+T3*$F$72 -> 252001608000
A5: 4 | B5: 회심타데미지 | C5: 1500000000 | D5: 1 | E5: 21501608 | F5: 5000 | G5: 110C | H5: =5000/2*(C5+5000*E5) -> 272520100000000 | I5: 272c | J5: 136c | O5: 한번업글가격 | P5: 50b | Q5: 100b | R5: 150b | S5: 200b | T5: 250b
A6: 5 | B6: 절멸타확률 | C6: 251751106392 | D6: 100 | E6: 800000000 | F6: 1000 | G6: 300C | H6: =1000/2*(C6+999*E6) -> 525475553196000 | I6: 376c | J6: 188c | N6: 데미지 | O6: 진행율 | P6: 0.2 | Q6: 0.4 | R6: 0.6 | S6: 0.8 | T6: 1
A7: 6 | B7: 절멸타데미지 | C7: 108986538392 | D7: 100 | E7: 420000000 | F7: 5000 | G7: 600C | H7: =5000/2*(C7+5000*E7) -> 5.5224663e+15 | I7: 810c | J7: 405c | O7: 5000 | P7: =$O7*P$2 -> 1000 | Q7: =$O7*Q$2 -> 2000 | R7: =$O7*R$2 -> 3000 | S7: =$O7*S$2 -> 4000 | T7: =$O7*T$2 -> 5000
P8: =$D$72+P7*$F$73 -> 23001608000 | Q8: =$D$72+Q7*$F$73 -> 44503216000 | R8: =$D$72+R7*$F$73 -> 66004824000 | S8: =$D$72+S7*$F$73 -> 87506432000 | T8: =$D$72+T7*$F$73 -> 109008040000
O9: 한번업글가격 | P9: 23b | Q9: 44b | R9: 66b | S9: 87b | T9: 110b
N11: 절멸타
N12: 공격력 | O12: 진행율 | P12: 0.2 | Q12: 0.4 | R12: 0.6 | S12: 0.8 | T12: 1
G13: 횟수 | I13: 1000 | O13: 1000 | P13: =$O13*P$2 -> 200 | Q13: =$O13*Q$2 -> 400 | R13: =$O13*R$2 -> 600 | S13: =$O13*S$2 -> 800 | T13: =$O13*T$2 -> 1000
G14: 회심타확률 | I14: =D72+I$13*F72 -> 252001608000 | J14: 250b | P14: =$D$74+P13*$F$74 -> 411751106392 | Q14: =$D$74+Q13*$F$74 -> 571751106392 | R14: =$D$74+R13*$F$74 -> 731751106392 | S14: =$D$74+S13*$F$74 -> 891751106392 | T14: =$D$74+T13*$F$74 -> 1051751106392
G15: 회심타데미지 | I15: =D72+I$13*F73 -> 23001608000 | J15: 100b | O15: 한번업글가격 | P15: 400b | Q15: 550b | R15: 700b | S15: 853b | T15: 1000b
N16: 데미지 | O16: 진행율 | P16: 0.2 | Q16: 0.4 | R16: 0.6 | S16: 0.8 | T16: 1
C17: 1A 100만 | D17: 1000000 | I17: 5000 | O17: 5000 | P17: =$O17*P$2 -> 1000 | Q17: =$O17*Q$2 -> 2000 | R17: =$O17*R$2 -> 3000 | S17: =$O17*S$2 -> 4000 | T17: =$O17*T$2 -> 5000
C18: 10A 1000만 | D18: 10000000 | H18: 초항 | P18: =$D$75+P17*$F$75 -> 528986538392 | Q18: =$D$75+Q17*$F$75 -> 948986538392 | R18: =$D$75+R17*$F$75 -> 1368986538392 | S18: =$D$75+S17*$F$75 -> 1788986538392 | T18: =$D$75+T17*$F$75 -> 2208986538392
C19: 100A 1억 | D19: 100000000 | G19: 절멸타 확률 | I19: =C4+(1000)*E4 -> 252001608000 | O19: 한번업글가격 | P19: 152b | Q19: 195b | R19: 238b | S19: 281b | T19: 324b
C20: 1B 10억 | D20: 1000000000 | G20: 절멸타 데미지 | I20: =C5+(5000)*E5 -> 109008040000
C21: 10B 100억 | D21: 10000000000
C22: 100B 1000억 | D22: 100000000000
C23: 1C 1조 | D23: 1000000000000 | G23: 합공식 | H23: n= | I23: 1000 | K23: 0.5
C24: 10C 10조 | D24: 10000000000000 | G24: 절멸타 확률 | I24: =I$23/2*((2*C6)+(I$23-1)*E6) -> 651351106392000 | J24: =I24/I24 -> 1 | K24: =I24*0.4 -> 260540442556800
C25: 100C 100조 | D25: 100000000000000 | G25: 절멸타 데미지 | I25: =I17/2*((2*C7)+(I17-1)*E7) -> 5.7938827e+15 | J25: =I25/I24 -> 8.8951759 | K25: =I25*0.4 -> 2.3175531e+15 | Z25: 1000000000
Y31: 랭킹 | Z31: 스테이지 | AA31: 20시간 | AB31: 노다지5 | AD31: 하루 총금화 | AE31: 골드증강량 | AI31: 강화석소탕 | AJ31: 20시간 | AK31: 강화석증강량
Y32: 1
Y33: 2 | Z33: 1055 | AA33: 950b | AB33: 67b | AC33: =67*5 -> 335 | AD33: =950+335 -> 1285 | AE33: 12.37 | AI33: 11a | AJ33: =SUM(AJ33:AJ34) -> 68 | AK33: 11.08
Y34: 10 | Z34: 855 | AA34: 590 | AB34: 40 | AC34: =AB34*5 -> 200 | AD34: =AC34+AA34 -> 790 | AE34: 8.87 | AI34: 5 | AJ34: 38 | AK34: 7.54
Y35: 흑천검 | Z35: 1216 | AA35: 1800 | AB35: 154 | AC35: =AB35*5 -> 770 | AD35: =AC35+AA35 -> 2570 | AE35: 20 | AI35: 34 | AJ35: 167 | AK35: 20
AD41: 10 | AE41: 300 | AF41: =AE41/AD41 -> 30
AD42: 72 | AE42: 300 | AF42: =AE42/AD42 -> 4.1666667
AA43: 신화 | AB43: 전설
X44: 증강량 | Y44: 0.4 | Z44: 0.2
H46: =G45 -> 0 | J46: =INT(I46*(1-I$55/100)) -> 0 | X46: 11각성 | Y46: =Y$44*6 -> 2.4 | Z46: =Z$44*6 -> 1.2
X47: 12각성 | Y47: =Y$44*6+Y46 -> 4.8 | Z47: =Z$44*6+Z46 -> 2.4
X48: 13각성 | Y48: =Y$44*6+Y47 -> 7.2 | Z48: =Z$44*6+Z47 -> 3.6
F53: 회심타 확률 | M53: 회심타 데미지
I55: 60 | Q55: 60
H56: 순수비용 | I56: 감면 | J56: 100 | K56: =0 -> 0 | P56: 순수비용 | Q56: 감면
D57: 1000 | E57: 0.1 | F57: 100 | H57: =F57/2*((2*D$72)+(F57-1)*F$72) -> 1389982959600 | I57: =INT(H57*(1-I$55/100)) -> 555993183840 | J57: =I57*0.6 -> 333595910304 | K57: =J57/(10^9) -> 333.59591 | M57: 5000 | N57: 0.05 | O57: =N57*M57 -> 250 | Q57: =O57/2*((2*D$73)+(O57-1)*F$73) -> 1044237549000 | R57: =INT(Q57*(1-Q$55/100)) -> 417695019600 | S57: =R57*1 -> 417695019600 | T57: =S57/(10^9) -> 417.69502
...
