Workbook

Sheet 보스체력
A1: 일반 | D1: 어려움 | I1: 극한 | Q1: 세짐 | S1: 어려움 | V1: 세짐 | X1: 극한 | AA1: 세짐
A2: 스테이지 | B2: 체력 | D2: 스테이지 | E2: 체력 | F2: 치환스테이지 | I2: 스테이지 | J2: 체력 | K2: 치환스테이지 | N2: 563 | P2: {=INDIRECT("b" & (N2+2))} -> 1.225e+37 | Q2: =P2/P$2 -> 1 | S2: 123 | U2: {=INDIRECT("d" & (S2+2))} -> 123 | V2: =U2/U$2 -> 1 | X2: 563 | Z2: {=INDIRECT("b" & (X2+2))} -> 1.225e+37 | AA2: =Z2/Z$2 -> 1
A3: 1 | B3: 50 | D3: 1 | E3: {=INDIRECT("b"&F3+2)} -> 9e+28 | F3: =INT((A3-1)*1.333333+400) -> 400 | I3: 1 | J3: {=INDIRECT("b"&K3+2)} -> 9.55e+61 | K3: =INT((A3-1)*40/30+900*40/30)+400 -> 1600 | N3: 564 | P3: {=INDIRECT("b" & (N3+2))} -> 1.45e+37 | Q3: =P3/$P$2 -> 1.1836735 | S3: 124 | U3: {=INDIRECT("d" & (S3+2))} -> 124 | V3: =U3/U$2 -> 1.0081301 | W3: 1 | X3: 564 | Z3: {=INDIRECT("b" & (X3+2))} -> 1.45e+37 | AA3: =Z3/$P$2 -> 1.1836735
A4: 2 | B4: 80 | D4: 2 | E4: {=INDIRECT("b"&F4+2)} -> 9.5e+28 | F4: =INT((A4-1)*1.333333+400) -> 401 | I4: 2 | J4: {=INDIRECT("b"&K4+2)} -> 9.775e+61 | K4: =INT((A4-1)*40/30+900*40/30)+400 -> 1601 | N4: 565 | P4: {=INDIRECT("b" & (N4+2))} -> 1.675e+37 | Q4: =P4/$P$2 -> 1.3673469 | S4: 125 | U4: {=INDIRECT("d" & (S4+2))} -> 125 | V4: =U4/U$2 -> 1.0162602 | W4: 2 | X4: 565 | Z4: {=INDIRECT("b" & (X4+2))} -> 1.675e+37 | AA4: =Z4/$P$2 -> 1.3673469
A5: 3 | B5: 120 | D5: 3 | E5: {=INDIRECT("b"&F5+2)} -> 1e+29 | F5: =INT((A5-1)*1.333333+400) -> 402 | I5: 3 | J5: {=INDIRECT("b"&K5+2)} -> 1e+62 | K5: =INT((A5-1)*40/30+900*40/30)+400 -> 1602 | N5: 566 | P5: {=INDIRECT("b" & (N5+2))} -> 1.9e+37 | Q5: =P5/$P$2 -> 1.5510204 | S5: 126 | U5: {=INDIRECT("d" & (S5+2))} -> 126 | V5: =U5/U$2 -> 1.0243902 | W5: 3 | X5: 566 | Z5: {=INDIRECT("b" & (X5+2))} -> 1.9e+37 | AA5: =Z5/$P$2 -> 1.5510204
A6: 4 | B6: 300 | D6: 4 | E6: {=INDIRECT("b"&F6+2)} -> 1.05e+29 | F6: =INT((A6-1)*1.333333+400) -> 403 | I6: 4 | J6: {=INDIRECT("b"&K6+2)} -> 1.45e+62 | K6: =INT((A6-1)*40/30+900*40/30)+400 -> 1604 | N6: 567 | P6: {=INDIRECT("b" & (N6+2))} -> 2.125e+37 | Q6: =P6/$P$2 -> 1.7346939 | S6: 127 | U6: {=INDIRECT("d" & (S6+2))} -> 127 | V6: =U6/U$2 -> 1.0325203 | W6: 4 | X6: 567 | Z6: {=INDIRECT("b" & (X6+2))} -> 2.125e+37 | AA6: =Z6/$P$2 -> 1.7346939
A7: 5 | B7: 700 | D7: 5 | E7: {=INDIRECT("b"&F7+2)} -> 1.5e+29 | F7: =INT((A7-1)*1.333333+400) -> 405 | I7: 5 | J7: {=INDIRECT("b"&K7+2)} -> 1.675e+62 | K7: =INT((A7-1)*40/30+900*40/30)+400 -> 1605 | N7: 568 | P7: {=INDIRECT("b" & (N7+2))} -> 2.35e+37 | Q7: =P7/$P$2 -> 1.9183673 | S7: 128 | U7: {=INDIRECT("d" & (S7+2))} -> 128 | V7: =U7/U$2 -> 1.0406504 | W7: 5 | X7: 568 | Z7: {=INDIRECT("b" & (X7+2))} -> 2.35e+37 | AA7: =Z7/$P$2 -> 1.9183673
A8: 6 | B8: 3000 | D8: 6 | E8: {=INDIRECT("b"&F8+2)} -> 2e+29 | F8: =INT((A8-1)*1.333333+400) -> 406 | I8: 6 | J8: {=INDIRECT("b"&K8+2)} -> 1.9e+62 | K8: =INT((A8-1)*40/30+900*40/30)+400 -> 1606 | N8: 569 | P8: {=INDIRECT("b" & (N8+2))} -> 2.575e+37 | Q8: =P8/$P$2 -> 2.1020408 | S8: 129 | U8: {=INDIRECT("d" & (S8+2))} -> 129 | V8: =U8/U$2 -> 1.0487805 | W8: 6 | X8: 569 | Z8: {=INDIRECT("b" & (X8+2))} -> 2.575e+37 | AA8: =Z8/$P$2 -> 2.1020408
A9: 7 | B9: 5000 | D9: 7 | E9: {=INDIRECT("b"&F9+2)} -> 2.5e+29 | F9: =INT((A9-1)*1.333333+400) -> 407 | I9: 7 | J9: {=INDIRECT("b"&K9+2)} -> 2.35e+62 | K9: =INT((A9-1)*40/30+900*40/30)+400 -> 1608 | N9: 570 | P9: {=INDIRECT("b" & (N9+2))} -> 2.8e+37 | Q9: =P9/$P$2 -> 2.2857143 | S9: 130 | U9: {=INDIRECT("d" & (S9+2))} -> 130 | V9: =U9/U$2 -> 1.0569106 | W9: 7 | X9: 570 | Z9: {=INDIRECT("b" & (X9+2))} -> 2.8e+37 | AA9: =Z9/$P$2 -> 2.2857143
A10: 8 | B10: 7000 | D10: 8 | E10: {=INDIRECT("b"&F10+2)} -> 3.5e+29 | F10: =INT((A10-1)*1.333333+400) -> 409 | I10: 8 | J10: {=INDIRECT("b"&K10+2)} -> 2.575e+62 | K10: =INT((A10-1)*40/30+900*40/30)+400 -> 1609 | N10: 571 | P10: {=INDIRECT("b" & (N10+2))} -> 3.025e+37 | Q10: =P10/$P$2 -> 2.4693878 | S10: 131 | U10: {=INDIRECT("d" & (S10+2))} -> 131 | V10: =U10/U$2 -> 1.0650407 | W10: 8 | X10: 571 | Z10: {=INDIRECT("b" & (X10+2))} -> 3.025e+37 | AA10: =Z10/$P$2 -> 2.4693878
A11: 9 | B11: 9000 | D11: 9 | E11: {=INDIRECT("b"&F11+2)} -> 4e+29 | F11: =INT((A11-1)*1.333333+400) -> 410 | I11: 9 | J11: {=INDIRECT("b"&K11+2)} -> 2.8e+62 | K11: =INT((A11-1)*40/30+900*40/30)+400 -> 1610 | N11: 572 | P11: {=INDIRECT("b" & (N11+2))} -> 3.25e+37 | Q11: =P11/$P$2 -> 2.6530612 | S11: 132 | U11: {=INDIRECT("d" & (S11+2))} -> 132 | V11: =U11/U$2 -> 1.0731707 | W11: 9 | X11: 572 | Z11: {=INDIRECT("b" & (X11+2))} -> 3.25e+37 | AA11: =Z11/$P$2 -> 2.6530612
A12: 10 | B12: 12000 | D12: 10 | E12: {=INDIRECT("b"&F12+2)} -> 4.5e+29 | F12: =INT((A12-1)*1.333333+400) -> 411 | I12: 10 | J12: {=INDIRECT("b"&K12+2)} -> 3.25e+62 | K12: =INT((A12-1)*40/30+900*40/30)+400 -> 1612 | N12: 573 | P12: {=INDIRECT("b" & (N12+2))} -> 3.475e+37 | Q12: =P12/$P$2 -> 2.8367347 | S12: 133 | U12: {=INDIRECT("d" & (S12+2))} -> 133 | V12: =U12/U$2 -> 1.0813008 | W12: 10 | X12: 573 | Z12: {=INDIRECT("b" & (X12+2))} -> 3.475e+37 | AA12: =Z12/$P$2 -> 2.8367347
A13: 11 | B13: 15000 | D13: 11 | E13: {=INDIRECT("b"&F13+2)} -> 5.5e+29 | F13: =INT((A13-1)*1.333333+400) -> 413 | I13: 11 | J13: {=INDIRECT("b"&K13+2)} -> 3.475e+62 | K13: =INT((A13-1)*40/30+900*40/30)+400 -> 1613 | N13: 574 | P13: {=INDIRECT("b" & (N13+2))} -> 3.7e+37 | Q13: =P13/$P$2 -> 3.0204082 | S13: 134 | U13: {=INDIRECT("d" & (S13+2))} -> 134 | V13: =U13/U$2 -> 1.0894309 | W13: 11 | X13: 574 | Z13: {=INDIRECT("b" & (X13+2))} -> 3.7e+37 | AA13: =Z13/$P$2 -> 3.0204082
A14: 12 | B14: 18000 | D14: 12 | E14: {=INDIRECT("b"&F14+2)} -> 6e+29 | F14: =INT((A14-1)*1.333333+400) -> 414 | I14: 12 | J14: {=INDIRECT("b"&K14+2)} -> 3.7e+62 | K14: =INT((A14-1)*40/30+900*40/30)+400 -> 1614 | N14: 575 | P14: {=INDIRECT("b" & (N14+2))} -> 3.925e+37 | Q14: =P14/$P$2 -> 3.2040816 | S14: 135 | U14: {=INDIRECT("d" & (S14+2))} -> 135 | V14: =U14/U$2 -> 1.097561 | W14: 12 | X14: 575 | Z14: {=INDIRECT("b" & (X14+2))} -> 3.925e+37 | AA14: =Z14/$P$2 -> 3.2040816
... A124: 122 | B124: 600000000000000 | D124: 122 | E124: {=INDIRECT("b"&F124+2)} -> 9.5e+36 | F124: =INT((A124-1)*1.333333+400) -> 561 | I124: 122 | J124: {=INDIRECT("b"&K124+2)} -> 9.775e+65 | K124: =INT((A124-1)*40/30+900*40/30)+400 -> 1761 | N124: 685 | P124: {=INDIRECT("b" & (N124+2))} -> 1.675e+40 | Q124: =P124/$P$2 -> 1367.3469 | S124: 245 | U124: {=INDIRECT("d" & (S124+2))} -> 245 | V124: =U124/U$2 -> 1.9918699 | W124: 122 | X124: 685 | Z124: {=INDIRECT("b" & (X124+2))} -> 1.675e+40 | AA124: =Z124/$P$2 -> 1367.3469
A125: 123 | B125: 700000000000000 | D125: 123 | E125: {=INDIRECT("b"&F125+2)} -> 1.225e+37 | F125: =INT((A125-123)*1.333333)+563 -> 563 | I125: 123 | J125: {=INDIRECT("b"&K125+2)} -> 1e+66 | K125: =INT((A125-1)*40/30+900*40/30)+400 -> 1762 | N125: 686 | P125: {=INDIRECT("b" & (N125+2))} -> 1.9e+40 | Q125: =P125/$P$2 -> 1551.0204 | S125: 246 | U125: {=INDIRECT("d" & (S125+2))} -> 246 | V125: =U125/U$2 -> 2 | W125: 123 | X125: 686 | Z125: {=INDIRECT("b" & (X125+2))} -> 1.9e+40 | AA125: =Z125/$P$2 -> 1551.0204
A126: 124 | B126: 800000000000000 | D126: 124 | E126: {=INDIRECT("b"&F126+2)} -> 1.45e+37 | F126: =INT((A126-123)*1.333333)+563 -> 564 | I126: 124 | J126: {=INDIRECT("b"&K126+2)} -> 1.45e+66 | K126: =INT((A126-1)*40/30+900*40/30)+400 -> 1764 | N126: 687 | P126: {=INDIRECT("b" & (N126+2))} -> 2.125e+40 | Q126: =P126/$P$2 -> 1734.6939 | S126: 247 | U126: {=INDIRECT("d" & (S126+2))} -> 247 | V126: =U126/U$2 -> 2.0081301 | W126: 124 | X126: 687 | Z126: {=INDIRECT("b" & (X126+2))} -> 2.125e+40 | AA126: =Z126/$P$2 -> 1734.6939
A127: 125 | B127: 900000000000000 | D127: 125 | E127: {=INDIRECT("b"&F127+2)} -> 1.675e+37 | F127: =INT((A127-123)*1.333333)+563 -> 565 | I127: 125 | J127: {=INDIRECT("b"&K127+2)} -> 1.675e+66 | K127: =INT((A127-1)*40/30+900*40/30)+400 -> 1765 | N127: 688 | P127: {=INDIRECT("b" & (N127+2))} -> 2.35e+40 | Q127: =P127/$P$2 -> 1918.3673 | S127: 248 | U127: {=INDIRECT("d" & (S127+2))} -> 248 | V127: =U127/U$2 -> 2.0162602 | W127: 125 | X127: 688 | Z127: {=INDIRECT("b" & (X127+2))} -> 2.35e+40 | AA127: =Z127/$P$2 -> 1918.3673
A128: 126 | B128: 1e+15 | D128: 126 | E128: {=INDIRECT("b"&F128+2)} -> 1.9e+37 | F128: =INT((A128-123)*1.333333)+563 -> 566 | I128: 126 | J128: {=INDIRECT("b"&K128+2)} -> 1.9e+66 | K128: =INT((A128-1)*40/30+900*40/30)+400 -> 1766 | N128: 689 | P128: {=INDIRECT("b" & (N128+2))} -> 2.575e+40 | Q128: =P128/$P$2 -> 2102.0408 | S128: 249 | U128: {=INDIRECT("d" & (S128+2))} -> 249 | V128: =U128/U$2 -> 2.0243902 | W128: 126 | X128: 689 | Z128: {=INDIRECT("b" & (X128+2))} -> 2.575e+40 | AA128: =Z128/$P$2 -> 2102.0408
A129: 127 | B129: 1.5e+15 | D129: 127 | E129: {=INDIRECT("b"&F129+2)} -> 2.35e+37 | F129: =INT((A129-123)*1.333333)+563 -> 568 | I129: 127 | J129: {=INDIRECT("b"&K129+2)} -> 2.35e+66 | K129: =INT((A129-1)*40/30+900*40/30)+400 -> 1768 | N129: 690 | P129: {=INDIRECT("b" & (N129+2))} -> 2.8e+40 | Q129: =P129/$P$2 -> 2285.7143 | S129: 250 | U129: {=INDIRECT("d" & (S129+2))} -> 250 | V129: =U129/U$2 -> 2.0325203 | W129: 127 | X129: 690 | Z129: {=INDIRECT("b" & (X129+2))} -> 2.8e+40 | AA129: =Z129/$P$2 -> 2285.7143
A130: 128 | B130: 2e+15 | D130: 128 | E130: {=INDIRECT("b"&F130+2)} -> 2.575e+37 | F130: =INT((A130-123)*1.333333)+563 -> 569 | I130: 128 | J130: {=INDIRECT("b"&K130+2)} -> 2.575e+66 | K130: =INT((A130-1)*40/30+900*40/30)+400 -> 1769 | N130: 691 | P130: {=INDIRECT("b" & (N130+2))} -> 3.025e+40 | Q130: =P130/$P$2 -> 2469.3878 | S130: 251 | U130: {=INDIRECT("d" & (S130+2))} -> 251 | V130: =U130/U$2 -> 2.0406504 | W130: 128 | X130: 691 | Z130: {=INDIRECT("b" & (X130+2))} -> 3.025e+40 | AA130: =Z130/$P$2 -> 2469.3878
A131: 129 | B131: 2.5e+15 | D131: 129 | E131: {=INDIRECT("b"&F131+2)} -> 2.8e+37 | F131: =INT((A131-123)*1.333333)+563 -> 570 | I131: 129 | J131: {=INDIRECT("b"&K131+2)} -> 2.8e+66 | K131: =INT((A131-1)*40/30+900*40/30)+400 -> 1770 | N131: 692 | P131: {=INDIRECT("b" & (N131+2))} -> 3.25e+40 | Q131: =P131/$P$2 -> 2653.0612 | S131: 252 | U131: {=INDIRECT("d" & (S131+2))} -> 252 | V131: =U131/U$2 -> 2.0487805 | W131: 129 | X131: 692 | Z131: {=INDIRECT("b" & (X131+2))} -> 3.25e+40 | AA131: =Z131/$P$2 -> 2653.0612
A132: 130 | B132: 3e+15 | D132: 130 | E132: {=INDIRECT("b"&F132+2)} -> 3.25e+37 | F132: =INT((A132-123)*1.333333)+563 -> 572 | I132: 130 | J132: {=INDIRECT("b"&K132+2)} -> 3.25e+66 | K132: =INT((A132-1)*40/30+900*40/30)+400 -> 1772 | N132: 693 | P132: {=INDIRECT("b" & (N132+2))} -> 3.475e+40 | Q132: =P132/$P$2 -> 2836.7347 | S132: 253 | U132: {=INDIRECT("d" & (S132+2))} -> 253 | V132: =U132/U$2 -> 2.0569106 | W132: 130 | X132: 693 | Z132: {=INDIRECT("b" & (X132+2))} -> 3.475e+40 | AA132: =Z132/$P$2 -> 2836.7347
A133: 131 | B133: 3.5e+15 | D133: 131 | E133: {=INDIRECT("b"&F133+2)} -> 3.475e+37 | F133: =INT((A133-123)*1.333333)+563 -> 573 | I133: 131 | J133: {=INDIRECT("b"&K133+2)} -> 3.475e+66 | K133: =INT((A133-1)*40/30+900*40/30)+400 -> 1773 | N133: 694 | P133: {=INDIRECT("b" & (N133+2))} -> 3.7e+40 | Q133: =P133/$P$2 -> 3020.4082 | S133: 254 | U133: {=INDIRECT("d" & (S133+2))} -> 254 | V133: =U133/U$2 -> 2.0650407 | W133: 131 | X133: 694 | Z133: {=INDIRECT("b" & (X133+2))} -> 3.7e+40 | AA133: =Z133/$P$2 -> 3020.4082
A134: 132 | B134: 4e+15 | D134: 132 | E134: {=INDIRECT("b"&F134+2)} -> 3.7e+37 | F134: =INT((A134-123)*1.333333)+563 -> 574 | I134: 132 | J134: {=INDIRECT("b"&K134+2)} -> 3.7e+66 | K134: =INT((A134-1)*40/30+900*40/30)+400 -> 1774 | N134: 695 | P134: {=INDIRECT("b" & (N134+2))} -> 3.925e+40 | Q134: =P134/$P$2 -> 3204.0816 | S134: 255 | U134: {=INDIRECT("d" & (S134+2))} -> 255 | V134: =U134/U$2 -> 2.0731707 | W134: 132 | X134: 695 | Z134: {=INDIRECT("b" & (X134+2))} -> 3.925e+40 | AA134: =Z134/$P$2 -> 3204.0816
A135: 133 | B135: 4.5e+15 | D135: 133 | E135: {=INDIRECT("b"&F135+2)} -> 4.15e+37 | F135: =INT((A135-123)*1.333333)+563 -> 576 | I135: 133 | J135: {=INDIRECT("b"&K135+2)} -> 4.15e+66 | K135: =INT((A135-1)*40/30+900*40/30)+400 -> 1776 | N135: 696 | P135: {=INDIRECT("b" & (N135+2))} -> 4.15e+40 | Q135: =P135/$P$2 -> 3387.7551 | S135: 256 | U135: {=INDIRECT("d" & (S135+2))} -> 256 | V135: =U135/U$2 -> 2.0813008 | W135: 133 | X135: 696 | Z135: {=INDIRECT("b" & (X135+2))} -> 4.15e+40 | AA135: =Z135/$P$2 -> 3387.7551
A136: 134 | B136: 5e+15 | D136: 134 | E136: {=INDIRECT("b"&F136+2)} -> 4.375e+37 | F136: =INT((A136-123)*1.333333)+563 -> 577 | I136: 134 | J136: {=INDIRECT("b"&K136+2)} -> 4.375e+66 | K136: =INT((A136-1)*40/30+900*40/30)+400 -> 1777 | N136: 697 | P136: {=INDIRECT("b" & (N136+2))} -> 4.375e+40 | Q136: =P136/$P$2 -> 3571.4286 | S136: 257 | U136: {=INDIRECT("d" & (S136+2))} -> 257 | V136: =U136/U$2 -> 2.0894309 | W136: 134 | X136: 697 | Z136: {=INDIRECT("b" & (X136+2))} -> 4.375e+40 | AA136: =Z136/$P$2 -> 3571.4286
... A440: 438 | B440: 8e+30 | D440: 438 | E440: {=INDIRECT("b"&F440+2)} -> 5.5e+47 | F440: =INT((A440-123)*1.333333)+563 -> 982 | I440: 438 | J440: {=INDIRECT("b"&K440+2)} -> 5.5e+76 | K440: =INT((A440-1)*40/30+900*40/30)+400 -> 2182 | N440: 1001 | P440: {=INDIRECT("b" & (N440+2))} -> 9.775e+47 | Q440: =P440/$P$2 -> 7.9795918e+10 | S440: 561 | U440: {=INDIRECT("d" & (S440+2))} -> 561 | V440: =U440/U$2 -> 4.5609756 | W440: 438 | X440: 1001 | Z440: {=INDIRECT("b" & (X440+2))} -> 9.775e+47 | AA440: =Z440/$P$2 -> 7.9795918e+10
A441: 439 | B441: 8.5e+30 | D441: 439 | E441: {=INDIRECT("b"&F441+2)} -> 5.95e+47 | F441: =INT((A441-123)*1.333333)+563 -> 984 | I441: 439 | J441: {=INDIRECT("b"&K441+2)} -> 5.95e+76 | K441: =INT((A441-1)*40/30+900*40/30)+400 -> 2184
A442: 440 | B442: 9e+30 | D442: 440 | E442: {=INDIRECT("b"&F442+2)} -> 6.175e+47 | F442: =INT((A442-123)*1.333333)+563 -> 985 | I442: 440 | J442: {=INDIRECT("b"&K442+2)} -> 6.175e+76 | K442: =INT((A442-1)*40/30+900*40/30)+400 -> 2185
A443: 441 | B443: 9.5e+30 | D443: 441 | E443: {=INDIRECT("b"&F443+2)} -> 6.4e+47 | F443: =INT((A443-123)*1.333333)+563 -> 986 | I443: 441 | J443: {=INDIRECT("b"&K443+2)} -> 6.4e+76 | K443: =INT((A443-1)*40/30+900*40/30)+400 -> 2186
A444: 442 | B444: 1e+31 | D444: 442 | E444: {=INDIRECT("b"&F444+2)} -> 6.85e+47 | F444: =INT((A444-123)*1.333333)+563 -> 988 | I444: 442 | J444: {=INDIRECT("b"&K444+2)} -> 6.85e+76 | K444: =INT((A444-1)*40/30+900*40/30)+400 -> 2188
A445: 443 | B445: 1.05e+31 | D445: 443 | E445: {=INDIRECT("b"&F445+2)} -> 7.075e+47 | F445: =INT((A445-123)*1.333333)+563 -> 989 | I445: 443 | J445: {=INDIRECT("b"&K445+2)} -> 7.075e+76 | K445: =INT((A445-1)*40/30+900*40/30)+400 -> 2189
A446: 444 | B446: 1.1e+31 | D446: 444 | E446: {=INDIRECT("b"&F446+2)} -> 7.3e+47 | F446: =INT((A446-123)*1.333333)+563 -> 990 | I446: 444 | J446: {=INDIRECT("b"&K446+2)} -> 7.3e+76 | K446: =INT((A446-1)*40/30+900*40/30)+400 -> 2190
A447: 445 | B447: 1.5e+31 | D447: 445 | E447: {=INDIRECT("b"&F447+2)} -> 7.75e+47 | F447: =INT((A447-123)*1.333333)+563 -> 992 | I447: 445 | J447: {=INDIRECT("b"&K447+2)} -> 7.75e+76 | K447: =INT((A447-1)*40/30+900*40/30)+400 -> 2192
A448: 446 | B448: 2e+31 | D448: 446 | E448: {=INDIRECT("b"&F448+2)} -> 7.975e+47 | F448: =INT((A448-123)*1.333333)+563 -> 993 | I448: 446 | J448: {=INDIRECT("b"&K448+2)} -> 7.975e+76 | K448: =INT((A448-1)*40/30+900*40/30)+400 -> 2193
A449: 447 | B449: 2.5e+31 | D449: 447 | E449: {=INDIRECT("b"&F449+2)} -> 8.2e+47 | F449: =INT((A449-123)*1.333333)+563 -> 994 | I449: 447 | J449: {=INDIRECT("b"&K449+2)} -> 8.2e+76 | K449: =INT((A449-1)*40/30+900*40/30)+400 -> 2194
A450: 448 | B450: 3e+31 | D450: 448 | E450: {=INDIRECT("b"&F450+2)} -> 8.65e+47 | F450: =INT((A450-123)*1.333333)+563 -> 996 | I450: 448 | J450: {=INDIRECT("b"&K450+2)} -> 8.65e+76 | K450: =INT((A450-1)*40/30+900*40/30)+400 -> 2196
A451: 449 | B451: 3.5e+31 | D451: 449 | E451: {=INDIRECT("b"&F451+2)} -> 8.875e+47 | F451: =INT((A451-123)*1.333333)+563 -> 997 | I451: 449 | J451: {=INDIRECT("b"&K451+2)} -> 8.875e+76 | K451: =INT((A451-1)*40/30+900*40/30)+400 -> 2197
A452: 450 | B452: 4e+31 | D452: 450 | E452: {=INDIRECT("b"&F452+2)} -> 9.1e+47 | F452: =INT((A452-123)*1.333333)+563 -> 998 | I452: 450 | J452: {=INDIRECT("b"&K452+2)} -> 9.1e+76 | K452: =INT((A452-1)*40/30+900*40/30)+400 -> 2198
...

Sheet 스테이지 계산
A1: 일반 | B1: 어려움 | C1: 어려움->일반 | D1: 극한 | E1: 극한->일반 | F1: 지옥 | G1: 지옥->일반 | H1: 연옥 | I1: 연옥->일반
A2: 1 | B2: 1 | D2: 1 | E2: 1560 | F2: 1 | G2: 2718 | H2: 1 | I2: 3876
A3: 2 | B3: 2 | D3: 2 | E3: =INT((D3-D$2)*1.3333333)+E$2 -> 1561 | F3: 2 | G3: =INT((F3-F$2)*1.3333333)+G$2 -> 2719 | H3: 2 | I3: =INT((H3-H$2)*1.3333333)+I$2 -> 3877
A4: 3 | B4: 3 | D4: 3 | E4: =INT((D4-D$2)*1.3333333)+E$2 -> 1562 | F4: 3 | G4: =INT((F4-F$2)*1.3333333)+G$2 -> 2720 | H4: 3 | I4: =INT((H4-H$2)*1.3333333)+I$2 -> 3878
A5: 4 | B5: 4 | D5: 4 | E5: =INT((D5-D$2)*1.3333333)+E$2 -> 1563 | F5: 4 | G5: =INT((F5-F$2)*1.3333333)+G$2 -> 2721 | H5: 4 | I5: =INT((H5-H$2)*1.3333333)+I$2 -> 3879
A6: 5 | B6: 5 | D6: 5 | E6: =INT((D6-D$2)*1.3333333)+E$2 -> 1565 | F6: 5 | G6: =INT((F6-F$2)*1.3333333)+G$2 -> 2723 | H6: 5 | I6: =INT((H6-H$2)*1.3333333)+I$2 -> 3881
A7: 6 | B7: 6 | D7: 6 | E7: =INT((D7-D$2)*1.3333333)+E$2 -> 1566 | F7: 6 | G7: =INT((F7-F$2)*1.3333333)+G$2 -> 2724 | H7: 6 | I7: =INT((H7-H$2)*1.3333333)+I$2 -> 3882
A8: 7 | B8: 7 | D8: 7 | E8: =INT((D8-D$2)*1.3333333)+E$2 -> 1567 | F8: 7 | G8: =INT((F8-F$2)*1.3333333)+G$2 -> 2725 | H8: 7 | I8: =INT((H8-H$2)*1.3333333)+I$2 -> 3883
A9: 8 | B9: 8 | D9: 8 | E9: =INT((D9-D$2)*1.3333333)+E$2 -> 1569 | F9: 8 | G9: =INT((F9-F$2)*1.3333333)+G$2 -> 2727 | H9: 8 | I9: =INT((H9-H$2)*1.3333333)+I$2 -> 3885
A10: 9 | B10: 9 | D10: 9 | E10: =INT((D10-D$2)*1.3333333)+E$2 -> 1570 | F10: 9 | G10: =INT((F10-F$2)*1.3333333)+G$2 -> 2728 | H10: 9 | I10: =INT((H10-H$2)*1.3333333)+I$2 -> 3886
A11: 10 | B11: 10 | D11: 10 | E11: =INT((D11-D$2)*1.3333333)+E$2 -> 1571 | F11: 10 | G11: =INT((F11-F$2)*1.3333333)+G$2 -> 2729 | H11: 10 | I11: =INT((H11-H$2)*1.3333333)+I$2 -> 3887
A12: 11 | B12: 11 | D12: 11 | E12: =INT((D12-D$2)*1.3333333)+E$2 -> 1573 | F12: 11 | G12: =INT((F12-F$2)*1.3333333)+G$2 -> 2731 | H12: 11 | I12: =INT((H12-H$2)*1.3333333)+I$2 -> 3889
A13: 12 | B13: 12 | D13: 12 | E13: =INT((D13-D$2)*1.3333333)+E$2 -> 1574 | F13: 12 | G13: =INT((F13-F$2)*1.3333333)+G$2 -> 2732 | H13: 12 | I13: =INT((H13-H$2)*1.3333333)+I$2 -> 3890
A14: 13 | B14: 13 | D14: 13 | E14: =INT((D14-D$2)*1.3333333)+E$2 -> 1575 | F14: 13 | G14: =INT((F14-F$2)*1.3333333)+G$2 -> 2733 | H14: 13 | I14: =INT((H14-H$2)*1.3333333)+I$2 -> 3891
... A121: 120 | B121: 120 | D121: 120 | E121: =INT((D121-D$2)*1.3333333)+E$2 -> 1718 | F121: 120 | G121: =INT((F121-F$2)*1.3333333)+G$2 -> 2876 | H121: 120 | I121: =INT((H121-H$2)*1.3333333)+I$2 -> 4034
A122: 121 | B122: 121 | C122: =562 -> 562 | D122: 121 | E122: =INT((D122-D$2)*1.3333333)+E$2 -> 1719 | F122: 121 | G122: =INT((F122-F$2)*1.3333333)+G$2 -> 2877 | H122: 121 | I122: =INT((H122-H$2)*1.3333333)+I$2 -> 4035
A123: 122 | B123: 122 | C123: =INT((B123-B$122)*1.3333333)+C$122 -> 563 | D123: 122 | E123: =INT((D123-D$2)*1.3333333)+E$2 -> 1721 | F123: 122 | G123: =INT((F123-F$2)*1.3333333)+G$2 -> 2879 | H123: 122 | I123: =INT((H123-H$2)*1.3333333)+I$2 -> 4037
A124: 123 | B124: 123 | C124: =INT((B124-B$122)*1.3333333)+C$122 -> 564 | D124: 123 | E124: =INT((D124-D$2)*1.3333333)+E$2 -> 1722 | F124: 123 | G124: =INT((F124-F$2)*1.3333333)+G$2 -> 2880 | H124: 123 | I124: =INT((H124-H$2)*1.3333333)+I$2 -> 4038
A125: 124 | B125: 124 | C125: =INT((B125-B$122)*1.3333333)+C$122 -> 565 | D125: 124 | E125: =INT((D125-D$2)*1.3333333)+E$2 -> 1723 | F125: 124 | G125: =INT((F125-F$2)*1.3333333)+G$2 -> 2881 | H125: 124 | I125: =INT((H125-H$2)*1.3333333)+I$2 -> 4039
A126: 125 | B126: 125 | C126: =INT((B126-B$122)*1.3333333)+C$122 -> 567 | D126: 125 | E126: =INT((D126-D$2)*1.3333333)+E$2 -> 1725 | F126: 125 | G126: =INT((F126-F$2)*1.3333333)+G$2 -> 2883 | H126: 125 | I126: =INT((H126-H$2)*1.3333333)+I$2 -> 4041
A127: 126 | B127: 126 | C127: =INT((B127-B$122)*1.3333333)+C$122 -> 568 | D127: 126 | E127: =INT((D127-D$2)*1.3333333)+E$2 -> 1726 | F127: 126 | G127: =INT((F127-F$2)*1.3333333)+G$2 -> 2884 | H127: 126 | I127: =INT((H127-H$2)*1.3333333)+I$2 -> 4042
A128: 127 | B128: 127 | C128: =INT((B128-B$122)*1.3333333)+C$122 -> 569 | D128: 127 | E128: =INT((D128-D$2)*1.3333333)+E$2 -> 1727 | F128: 127 | G128: =INT((F128-F$2)*1.3333333)+G$2 -> 2885 | H128: 127 | I128: =INT((H128-H$2)*1.3333333)+I$2 -> 4043
A129: 128 | B129: 128 | C129: =INT((B129-B$122)*1.3333333)+C$122 -> 571 | D129: 128 | E129: =INT((D129-D$2)*1.3333333)+E$2 -> 1729 | F129: 128 | G129: =INT((F129-F$2)*1.3333333)+G$2 -> 2887 | H129: 128 | I129: =INT((H129-H$2)*1.3333333)+I$2 -> 4045
A130: 129 | B130: 129 | C130: =INT((B130-B$122)*1.3333333)+C$122 -> 572 | D130: 129 | E130: =INT((D130-D$2)*1.3333333)+E$2 -> 1730 | F130: 129 | G130: =INT((F130-F$2)*1.3333333)+G$2 -> 2888 | H130: 129 | I130: =INT((H130-H$2)*1.3333333)+I$2 -> 4046
A131: 130 | B131: 130 | C131: =INT((B131-B$122)*1.3333333)+C$122 -> 573 | D131: 130 | E131: =INT((D131-D$2)*1.3333333)+E$2 -> 1731 | F131: 130 | G131: =INT((F131-F$2)*1.3333333)+G$2 -> 2889 | H131: 130 | I131: =INT((H131-H$2)*1.3333333)+I$2 -> 4047
A132: 131 | B132: 131 | C132: =INT((B132-B$122)*1.3333333)+C$122 -> 575 | D132: 131 | E132: =INT((D132-D$2)*1.3333333)+E$2 -> 1733 | F132: 131 | G132: =INT((F132-F$2)*1.3333333)+G$2 -> 2891 | H132: 131 | I132: =INT((H132-H$2)*1.3333333)+I$2 -> 4049
A133: 132 | B133: 132 | C133: =INT((B133-B$122)*1.3333333)+C$122 -> 576 | D133: 132 | E133: =INT((D133-D$2)*1.3333333)+E$2 -> 1734 | F133: 132 | G133: =INT((F133-F$2)*1.3333333)+G$2 -> 2892 | H133: 132 | I133: =INT((H133-H$2)*1.3333333)+I$2 -> 4050
A134: 133 | B134: 133 | C134: =INT((B134-B$122)*1.3333333)+C$122 -> 577 | D134: 133 | E134: =INT((D134-D$2)*1.3333333)+E$2 -> 1735 | F134: 133 | G134: =INT((F134-F$2)*1.3333333)+G$2 -> 2893 | H134: 133 | I134: =INT((H134-H$2)*1.3333333)+I$2 -> 4051
... A1565: 1564 | B1565: 1564 | C1565: =INT((B1565-B$122)*1.3333333)+C$122 -> 2485 | D1565: 1564 | E1565: =INT((D1565-D$2)*1.3333333)+E$2 -> 3643 | F1565: 1564 | G1565: =INT((F1565-F$2)*1.3333333)+G$2 -> 4801 | H1565: 1564 | I1565: =INT((H1565-H$2)*1.3333333)+I$2 -> 5959

Sheet 무릉전보스체력
A1: 스테이지 | B1: 1번값 | C1: 2번값 | D1: 3번값 | E1: 4번값 | F1: 5번값 | G1: 6번값 | H1: 7번값 | I1: 8번값 | J1: 9번값 | U1: 스테이지 | V1: 초월석(마리당) | W1: 안설(마리당) | X1: 강화석 (Per 5Stage) | Y1: 인봉 (Per 5Stage) | Z1: 다이아 (Per 5Stage) | AA1: 화련(Per 20Stage) | AC1: 무릉전스테이지 | AE1: 강화석지급량
A2: 1 | B2: 50000000 | C2: 1 | D2: 1 | E2: 1 | F2: 1 | G2: 1 | H2: 1 | I2: 1 | J2: 1 | K2: =J2*I2*H2*G2*F2*E2*D2*C2*B2 -> 50000000 | L2: =MATCH(K2, 보스체력!#REF!, 1) -> #REF! | O2: 스테이지 값 | P2: 1207 | R2: 강화석 | S2: 다이아 | U2: 1 | V2: 100 | W2: 1 | X2: 100 | Y2: 1 | Z2: 300 | AA2: 1 | AC2: 1 | AD2: =INT(AC2/5)+1 -> 1 | AE2: {=INDEX(X:X, AD2+1)*AC2} -> 100
A3: 2 | B3: 100000000 | C3: 1 | D3: 1 | E3: 1 | F3: 1 | G3: 1 | H3: 1 | I3: 1 | J3: 1 | K3: =J3*I3*H3*G3*F3*E3*D3*C3*B3 -> 100000000 | L3: =MATCH(K3, 보스체력!#REF!, 1) -> #REF! | O3: 무릉전 클리어 | P3: 265 | Q3: =P3-6 -> 259 | R3: {=INDEX(AE:AE, P3)} -> 1399200 | S3: =INDEX(U:U, MATCH(P2, L:L, 1)) -> #N/A | U3: 2 | V3: 150 | W3: 1 | X3: 200 | Y3: 2 | Z3: 600 | AA3: 2 | AC3: 2 | AD3: =INT(AC3/5)+1 -> 1 | AE3: {=INDEX(X:X, AD3+1)*AC3} -> 200
A4: 3 | B4: 200000000 | C4: 1 | D4: 1 | E4: 1 | F4: 1 | G4: 1 | H4: 1 | I4: 1 | J4: 1 | K4: =J4*I4*H4*G4*F4*E4*D4*C4*B4 -> 200000000 | L4: =MATCH(K4, 보스체력!#REF!, 1) -> #REF! | U4: 3 | V4: 300 | W4: 1 | X4: 300 | Y4: 3 | Z4: 900 | AA4: 3 | AC4: 3 | AD4: =INT(AC4/5)+1 -> 1 | AE4: {=INDEX(X:X, AD4+1)*AC4} -> 300
A5: 4 | B5: 500000000 | C5: 1 | D5: 1 | E5: 1 | F5: 1 | G5: 1 | H5: 1 | I5: 1 | J5: 1 | K5: =J5*I5*H5*G5*F5*E5*D5*C5*B5 -> 500000000 | L5: =MATCH(K5, 보스체력!#REF!, 1) -> #REF! | R5: {=INDIRECT("X" &214)} -> 0 | U5: 4 | V5: 540 | W5: 1 | X5: 400 | Y5: 4 | Z5: 1200 | AA5: 4 | AC5: 4 | AD5: =INT(AC5/5)+1 -> 1 | AE5: {=INDEX(X:X, AD5+1)*AC5} -> 400
A6: 5 | B6: 100000000 | C6: 10 | D6: 1 | E6: 1 | F6: 1 | G6: 1 | H6: 1 | I6: 1 | J6: 1 | K6: =J6*I6*H6*G6*F6*E6*D6*C6*B6 -> 1000000000 | L6: =MATCH(K6, 보스체력!#REF!, 1) -> #REF! | O6: 입장권 개수 | P6: 증강량 | Q6: 강화석 | R6: 최종 강화석 | U6: 5 | V6: 950 | W6: 1 | X6: 500 | Y6: 5 | Z6: 1500 | AA6: 5 | AC6: 5 | AD6: =INT(AC6/5)+1 -> 2 | AE6: {=INDEX(X:X, AD6+1)*AC6} -> 1000
A7: 6 | B7: 300000000 | C7: 10 | D7: 1 | E7: 1 | F7: 1 | G7: 1 | H7: 1 | I7: 1 | J7: 1 | K7: =J7*I7*H7*G7*F7*E7*D7*C7*B7 -> 3000000000 | L7: =MATCH(K7, 보스체력!#REF!, 1) -> #REF! | O7: 4 | Q7: =R3 -> 1399200 | R7: =Q7*P7*O7 -> 0 | U7: 6 | V7: 1460 | W7: 1 | X7: 600 | Y7: 6 | Z7: 1800 | AA7: 6 | AC7: 6 | AD7: =INT(AC7/5)+1 -> 2 | AE7: {=INDEX(X:X, AD7+1)*AC7} -> 1200
A8: 7 | B8: 500000000 | C8: 10 | D8: 1 | E8: 1 | F8: 1 | G8: 1 | H8: 1 | I8: 1 | J8: 1 | K8: =J8*I8*H8*G8*F8*E8*D8*C8*B8 -> 5000000000 | L8: =MATCH(K8, 보스체력!#REF!, 1) -> #REF! | U8: 7 | V8: 1970 | W8: 2 | X8: 700 | Y8: 7 | Z8: 2100 | AA8: 7 | AC8: 7 | AD8: =INT(AC8/5)+1 -> 2 | AE8: {=INDEX(X:X, AD8+1)*AC8} -> 1400
A9: 8 | B9: 700000000 | C9: 10 | D9: 1 | E9: 1 | F9: 1 | G9: 1 | H9: 1 | I9: 1 | J9: 1 | K9: =J9*I9*H9*G9*F9*E9*D9*C9*B9 -> 7000000000 | L9: =MATCH(K9, 보스체력!#REF!, 1) -> #REF! | U9: 8 | V9: 2480 | W9: 2 | X9: 800 | Y9: 8 | Z9: 2400 | AA9: 8 | AC9: 8 | AD9: =INT(AC9/5)+1 -> 2 | AE9: {=INDEX(X:X, AD9+1)*AC9} -> 1600
A10: 9 | B10: 100000000 | C10: 100 | D10: 1 | E10: 1 | F10: 1 | G10: 1 | H10: 1 | I10: 1 | J10: 1 | K10: =J10*I10*H10*G10*F10*E10*D10*C10*B10 -> 10000000000 | L10: =MATCH(K10, 보스체력!#REF!, 1) -> #REF! | U10: 9 | V10: 2990 | W10: 2 | X10: 900 | Y10: 9 | Z10: 2700 | AA10: 9 | AC10: 9 | AD10: =INT(AC10/5)+1 -> 2 | AE10: {=INDEX(X:X, AD10+1)*AC10} -> 1800
A11: 10 | B11: 500000000 | C11: 100 | D11: 1 | E11: 1 | F11: 1 | G11: 1 | H11: 1 | I11: 1 | J11: 1 | K11: =J11*I11*H11*G11*F11*E11*D11*C11*B11 -> 50000000000 | L11: =MATCH(K11, 보스체력!#REF!, 1) -> #REF! | O11: 일반 | P11: 고급 | Q11: 희귀 | R11: 영웅 | S11: 전설 | T11: 신화 | U11: 10 | V11: 4010 | W11: 2 | X11: 1000 | Y11: 10 | Z11: 3000 | AA11: 10 | AC11: 10 | AD11: =INT(AC11/5)+1 -> 3 | AE11: {=INDEX(X:X, AD11+1)*AC11} -> 3000
A12: 11 | B12: 800000000 | C12: 100 | D12: 1 | E12: 1 | F12: 1 | G12: 1 | H12: 1 | I12: 1 | J12: 1 | K12: =J12*I12*H12*G12*F12*E12*D12*C12*B12 -> 80000000000 | L12: =MATCH(K12, 보스체력!#REF!, 1) -> #REF! | M12: 표류자 | N12: 7 | O12: 1 | P12: 2 | Q12: 3 | R12: 4 | S12: 6 | T12: 10 | U12: 11 | V12: 5030 | W12: 2 | X12: 1100 | Y12: 11 | Z12: 3300 | AA12: 10 | AC12: 11 | AD12: =INT(AC12/5)+1 -> 3 | AE12: {=INDEX(X:X, AD12+1)*AC12} -> 3300
A13: 12 | B13: 100000000 | C13: 1000 | D13: 1 | E13: 1 | F13: 1 | G13: 1 | H13: 1 | I13: 1 | J13: 1 | K13: =J13*I13*H13*G13*F13*E13*D13*C13*B13 -> 100000000000 | L13: =MATCH(K13, 보스체력!#REF!, 1) -> #REF! | M13: 무사 | N13: 7 | O13: 2 | P13: 3 | Q13: 4 | R13: 5 | S13: 10 | T13: 18 | U13: 12 | V13: 6050 | W13: 2 | X13: 1200 | Y13: 12 | Z13: 3600 | AA13: 10 | AC13: 12 | AD13: =INT(AC13/5)+1 -> 3 | AE13: {=INDEX(X:X, AD13+1)*AC13} -> 3600
A14: 13 | B14: 500000000 | C14: 1000 | D14: 1 | E14: 1 | F14: 1 | G14: 1 | H14: 1 | I14: 1 | J14: 1 | K14: =J14*I14*H14*G14*F14*E14*D14*C14*B14 -> 500000000000 | L14: =MATCH(K14, 보스체력!#REF!, 1) -> #REF! | M14: 검객 | N14: 7 | O14: 3 | P14: 4 | Q14: 5 | R14: 7 | S14: 13 | T14: 21 | U14: 13 | V14: 7070 | W14: 3 | X14: 1300 | Y14: 13 | Z14: 3900 | AA14: 10 | AC14: 13 | AD14: =INT(AC14/5)+1 -> 3 | AE14: {=INDEX(X:X, AD14+1)*AC14} -> 3900
A15: 14 | B15: 800000000 | C15: 1000 | D15: 1 | E15: 1 | F15: 1 | G15: 1 | H15: 1 | I15: 1 | J15: 1 | K15: =J15*I15*H15*G15*F15*E15*D15*C15*B15 -> 800000000000 | L15: =MATCH(K15, 보스체력!#REF!, 1) -> #REF! | M15: 투사 | N15: 7 | O15: 4 | P15: 5 | Q15: 6 | R15: 8 | S15: 15 | T15: 25 | U15: 14 | V15: 8100 | W15: 3 | X15: 1400 | Y15: 14 | Z15: 4200 | AA15: 10 | AC15: 14 | AD15: =INT(AC15/5)+1 -> 3 | AE15: {=INDEX(X:X, AD15+1)*AC15} -> 4200
A16: 15 | B16: 100000000 | C16: 10000 | D16: 1 | E16: 1 | F16: 1 | G16: 1 | H16: 1 | I16: 1 | J16: 1 | K16: =J16*I16*H16*G16*F16*E16*D16*C16*B16 -> 1000000000000 | L16: =MATCH(K16, 보스체력!#REF!, 1) -> #REF! | M16: 검제 | N16: 7 | O16: 5 | P16: 6 | Q16: 7 | R16: 9 | S16: 18 | T16: 30 | U16: 15 | V16: 9120 | W16: 3 | X16: 1500 | Y16: 15 | Z16: 4500 | AA16: 10 | AC16: 15 | AD16: =INT(AC16/5)+1 -> 4 | AE16: {=INDEX(X:X, AD16+1)*AC16} -> 6000
A17: 16 | B17: 300000000 | C17: 10000 | D17: 1 | E17: 1 | F17: 1 | G17: 1 | H17: 1 | I17: 1 | J17: 1 | K17: =J17*I17*H17*G17*F17*E17*D17*C17*B17 -> 3000000000000 | L17: =MATCH(K17, 보스체력!#REF!, 1) -> #REF! | M17: 투신 | N17: 7 | O17: 6 | P17: 7 | Q17: 8 | R17: 10 | S17: 20 | T17: 33 | U17: 16 | V17: 10140 | W17: 3 | X17: 1600 | Y17: 16 | Z17: 4800 | AA17: 10 | AC17: 16 | AD17: =INT(AC17/5)+1 -> 4 | AE17: {=INDEX(X:X, AD17+1)*AC17} -> 6400
A18: 17 | B18: 500000000 | C18: 10000 | D18: 1 | E18: 1 | F18: 1 | G18: 1 | H18: 1 | I18: 1 | J18: 1 | K18: =J18*I18*H18*G18*F18*E18*D18*C18*B18 -> 5000000000000 | L18: =MATCH(K18, 보스체력!#REF!, 1) -> #REF! | M18: 패왕 | N18: 7 | O18: 6 | P18: 7 | Q18: 8 | R18: 10 | S18: 20 | T18: 33 | U18: 17 | V18: 11160 | W18: 3 | X18: 1700 | Y18: 17 | Z18: 5100 | AA18: 10 | AC18: 17 | AD18: =INT(AC18/5)+1 -> 4 | AE18: {=INDEX(X:X, AD18+1)*AC18} -> 6800
A19: 18 | B19: 700000000 | C19: 10000 | D19: 1 | E19: 1 | F19: 1 | G19: 1 | H19: 1 | I19: 1 | J19: 1 | K19: =J19*I19*H19*G19*F19*E19*D19*C19*B19 -> 7000000000000 | L19: =MATCH(K19, 보스체력!#REF!, 1) -> #REF! | M19: 검선 | N19: 7 | O19: 6 | P19: 7 | Q19: 8 | R19: 10 | S19: 20 | T19: 33 | U19: 18 | V19: 12180 | W19: 3 | X19: 1800 | Y19: 18 | Z19: 5400 | AA19: 10 | AC19: 18 | AD19: =INT(AC19/5)+1 -> 4 | AE19: {=INDEX(X:X, AD19+1)*AC19} -> 7200
A20: 19 | B20: 900000000 | C20: 10000 | D20: 1 | E20: 1 | F20: 1 | G20: 1 | H20: 1 | I20: 1 | J20: 1 | K20: =J20*I20*H20*G20*F20*E20*D20*C20*B20 -> 9000000000000 | L20: =MATCH(K20, 보스체력!#REF!, 1) -> #REF! | N20: 7 | O20: 6 | P20: 7 | Q20: 8 | R20: 10 | S20: 20 | T20: 33 | U20: 19 | V20: 13210 | W20: 4 | X20: 1900 | Y20: 19 | Z20: 5700 | AA20: 10 | AC20: 19 | AD20: =INT(AC20/5)+1 -> 4 | AE20: {=INDEX(X:X, AD20+1)*AC20} -> 7600
A21: 20 | B21: 100000000 | C21: 100000 | D21: 1 | E21: 1 | F21: 1 | G21: 1 | H21: 1 | I21: 1 | J21: 1 | K21: =J21*I21*H21*G21*F21*E21*D21*C21*B21 -> 10000000000000 | L21: =MATCH(K21, 보스체력!#REF!, 1) -> #REF! | O21: =SUM(O12:O20)*6 -> 234 | P21: =SUM(P12:P20)*6 -> 288 | Q21: =SUM(Q12:Q20)*6 -> 342 | R21: =SUM(R12:R20)*6 -> 438 | S21: =SUM(S12:S20)*6 -> 852 | T21: =SUM(T12:T20)*6 -> 1416 | U21: 20 | V21: 15060 | W21: 4 | X21: 2000 | Y21: 20 | Z21: 6000 | AA21: 10 | AC21: 20 | AD21: =INT(AC21/5)+1 -> 5 | AE21: {=INDEX(X:X, AD21+1)*AC21} -> 10000
A22: 21 | B22: 300000000 | C22: 100000 | D22: 1 | E22: 1 | F22: 1 | G22: 1 | H22: 1 | I22: 1 | J22: 1 | K22: =J22*I22*H22*G22*F22*E22*D22*C22*B22 -> 30000000000000 | L22: =MATCH(K22, 보스체력!#REF!, 1) -> #REF! | U22: 21 | V22: 16900 | W22: 4 | X22: 2100 | Y22: 20 | Z22: 6300 | AA22: 10 | AC22: 21 | AD22: =INT(AC22/5)+1 -> 5 | AE22: {=INDEX(X:X, AD22+1)*AC22} -> 10500
A23: 22 | B23: 500000000 | C23: 100000 | D23: 1 | E23: 1 | F23: 1 | G23: 1 | H23: 1 | I23: 1 | J23: 1 | K23: =J23*I23*H23*G23*F23*E23*D23*C23*B23 -> 50000000000000 | L23: =MATCH(K23, 보스체력!#REF!, 1) -> #REF! | U23: 22 | V23: 18700 | W23: 4 | X23: 2200 | Y23: 20 | Z23: 6600 | AA23: 10 | AC23: 22 | AD23: =INT(AC23/5)+1 -> 5 | AE23: {=INDEX(X:X, AD23+1)*AC23} -> 11000
A24: 23 | B24: 700000000 | C24: 100000 | D24: 1 | E24: 1 | F24: 1 | G24: 1 | H24: 1 | I24: 1 | J24: 1 | K24: =J24*I24*H24*G24*F24*E24*D24*C24*B24 -> 70000000000000 | L24: =MATCH(K24, 보스체력!#REF!, 1) -> #REF! | U24: 23 | V24: 20600 | W24: 4 | X24: 2300 | Y24: 20 | Z24: 6900 | AA24: 10 | AC24: 23 | AD24: =INT(AC24/5)+1 -> 5 | AE24: {=INDEX(X:X, AD24+1)*AC24} -> 11500
A25: 24 | B25: 900000000 | C25: 100000 | D25: 1 | E25: 1 | F25: 1 | G25: 1 | H25: 1 | I25: 1 | J25: 1 | K25: =J25*I25*H25*G25*F25*E25*D25*C25*B25 -> 90000000000000 | L25: =MATCH(K25, 보스체력!#REF!, 1) -> #REF! | U25: 24 | V25: 22470 | W25: 4 | X25: 2400 | Y25: 20 | Z25: 7200 | AA25: 10 | AC25: 24 | AD25: =INT(AC25/5)+1 -> 5 | AE25: {=INDEX(X:X, AD25+1)*AC25} -> 12000
A26: 25 | B26: 100000000 | C26: 1000000 | D26: 1 | E26: 1 | F26: 1 | G26: 1 | H26: 1 | I26: 1 | J26: 1 | K26: =J26*I26*H26*G26*F26*E26*D26*C26*B26 -> 100000000000000 | L26: =MATCH(K26, 보스체력!#REF!, 1) -> #REF! | U26: 25 | V26: 24300 | W26: 5 | X26: 2500 | Y26: 20 | Z26: 7500 | AA26: 10 | AC26: 25 | AD26: =INT(AC26/5)+1 -> 6 | AE26: {=INDEX(X:X, AD26+1)*AC26} -> 15000
A27: 26 | B27: 300000000 | C27: 1000000 | D27: 1 | E27: 1 | F27: 1 | G27: 1 | H27: 1 | I27: 1 | J27: 1 | K27: =J27*I27*H27*G27*F27*E27*D27*C27*B27 -> 300000000000000 | L27: =MATCH(K27, 보스체력!#REF!, 1) -> #REF! | U27: 26 | V27: 26170 | W27: 5 | X27: 2600 | Y27: 20 | Z27: 7800 | AA27: 10 | AC27: 26 | AD27: =INT(AC27/5)+1 -> 6 | AE27: {=INDEX(X:X, AD27+1)*AC27} -> 15600
A28: 27 | B28: 500000000 | C28: 1000000 | D28: 1 | E28: 1 | F28: 1 | G28: 1 | H28: 1 | I28: 1 | J28: 1 | K28: =J28*I28*H28*G28*F28*E28*D28*C28*B28 -> 500000000000000 | L28: =MATCH(K28, 보스체력!#REF!, 1) -> #REF! | U28: 27 | V28: 28000 | W28: 5 | X28: 2700 | Y28: 20 | Z28: 8100 | AA28: 10 | AC28: 27 | AD28: =INT(AC28/5)+1 -> 6 | AE28: {=INDEX(X:X, AD28+1)*AC28} -> 16200
A29: 28 | B29: 700000000 | C29: 1000000 | D29: 1 | E29: 1 | F29: 1 | G29: 1 | H29: 1 | I29: 1 | J29: 1 | K29: =J29*I29*H29*G29*F29*E29*D29*C29*B29 -> 700000000000000 | L29: =MATCH(K29, 보스체력!#REF!, 1) -> #REF! | U29: 28 | V29: 29800 | W29: 5 | X29: 2800 | Y29: 20 | Z29: 8400 | AA29: 10 | AC29: 28 | AD29: =INT(AC29/5)+1 -> 6 | AE29: {=INDEX(X:X, AD29+1)*AC29} -> 16800
A30: 29 | B30: 900000000 | C30: 1000000 | D30: 1 | E30: 1 | F30: 1 | G30: 1 | H30: 1 | I30: 1 | J30: 1 | K30: =J30*I30*H30*G30*F30*E30*D30*C30*B30 -> 900000000000000 | L30: =MATCH(K30, 보스체력!#REF!, 1) -> #REF! | U30: 29 | V30: 31730 | W30: 5 | X30: 2900 | Y30: 20 | Z30: 8700 | AA30: 10 | AC30: 29 | AD30: =INT(AC30/5)+1 -> 6 | AE30: {=INDEX(X:X, AD30+1)*AC30} -> 17400
A31: 30 | B31: 100000000 | C31: 10000000 | D31: 1 | E31: 1 | F31: 1 | G31: 1 | H31: 1 | I31: 1 | J31: 1 | K31: =J31*I31*H31*G31*F31*E31*D31*C31*B31 -> 1e+15 | L31: =MATCH(K31, 보스체력!#REF!, 1) -> #REF! | U31: 30 | V31: 34000 | W31: 5 | X31: 3000 | Y31: 20 | Z31: 9000 | AA31: 10 | AC31: 30 | AD31: =INT(AC31/5)+1 -> 7 | AE31: {=INDEX(X:X, AD31+1)*AC31} -> 21000
A32: 31 | B32: 300000000 | C32: 10000000 | D32: 1 | E32: 1 | F32: 1 | G32: 1 | H32: 1 | I32: 1 | J32: 1 | K32: =J32*I32*H32*G32*F32*E32*D32*C32*B32 -> 3e+15 | L32: =MATCH(K32, 보스체력!#REF!, 1) -> #REF! | U32: 31 | V32: 36400 | W32: 6 | X32: 3100 | Y32: 20 | Z32: 9300 | AA32: 10 | AC32: 31 | AD32: =INT(AC32/5)+1 -> 7 | AE32: {=INDEX(X:X, AD32+1)*AC32} -> 21700
A33: 32 | B33: 500000000 | C33: 10000000 | D33: 1 | E33: 1 | F33: 1 | G33: 1 | H33: 1 | I33: 1 | J33: 1 | K33: =J33*I33*H33*G33*F33*E33*D33*C33*B33 -> 5e+15 | L33: =MATCH(K33, 보스체력!#REF!, 1) -> #REF! | U33: 32 | V33: 39000 | W33: 6 | X33: 3200 | Y33: 20 | Z33: 9600 | AA33: 10 | AC33: 32 | AD33: =INT(AC33/5)+1 -> 7 | AE33: {=INDEX(X:X, AD33+1)*AC33} -> 22400
... A201: 200 | B201: 955000000 | C201: 100000000 | D201: 100000000 | E201: 100000000 | F201: 100000000 | G201: 100 | H201: 1 | I201: 1 | J201: 1 | K201: =J201*I201*H201*G201*F201*E201*D201*C201*B201 -> 9.55e+42 | L201: =MATCH(K201, 보스체력!#REF!, 1) -> #REF! | U201: 200 | V201: 435000 | W201: 10 | X201: 20000 | Y201: 20 | Z201: 15000 | AA201: 10 | AC201: 200 | AD201: =INT(AC201/5)+1 -> 41 | AE201: {=INDEX(X:X, AD201+1)*AC201} -> 820000
A202: 201 | B202: 145000000 | C202: 100000000 | D202: 100000000 | E202: 100000000 | F202: 100000000 | G202: 1000 | H202: 1 | I202: 1 | J202: 1 | K202: =J202*I202*H202*G202*F202*E202*D202*C202*B202 -> 1.45e+43 | L202: =MATCH(K202, 보스체력!#REF!, 1) -> #REF! | AC202: 201 | AD202: =INT(AC202/5)+1 -> 41 | AE202: {=INDEX(X:X, AD202+1)*AC202} -> 824100
A203: 202 | B203: 235000000 | C203: 100000000 | D203: 100000000 | E203: 100000000 | F203: 100000000 | G203: 1000 | H203: 1 | I203: 1 | J203: 1 | K203: =J203*I203*H203*G203*F203*E203*D203*C203*B203 -> 2.35e+43 | L203: =MATCH(K203, 보스체력!#REF!, 1) -> #REF! | AC203: 202 | AD203: =INT(AC203/5)+1 -> 41 | AE203: {=INDEX(X:X, AD203+1)*AC203} -> 828200
A204: 203 | B204: 325000000 | C204: 100000000 | D204: 100000000 | E204: 100000000 | F204: 100000000 | G204: 1000 | H204: 1 | I204: 1 | J204: 1 | K204: =J204*I204*H204*G204*F204*E204*D204*C204*B204 -> 3.25e+43 | L204: =MATCH(K204, 보스체력!#REF!, 1) -> #REF! | AC204: 203 | AD204: =INT(AC204/5)+1 -> 41 | AE204: {=INDEX(X:X, AD204+1)*AC204} -> 832300
A205: 204 | B205: 415000000 | C205: 100000000 | D205: 100000000 | E205: 100000000 | F205: 100000000 | G205: 1000 | H205: 1 | I205: 1 | J205: 1 | K205: =J205*I205*H205*G205*F205*E205*D205*C205*B205 -> 4.15e+43 | L205: =MATCH(K205, 보스체력!#REF!, 1) -> #REF! | AC205: 204 | AD205: =INT(AC205/5)+1 -> 41 | AE205: {=INDEX(X:X, AD205+1)*AC205} -> 836400
A206: 205 | B206: 505000000 | C206: 100000000 | D206: 100000000 | E206: 100000000 | F206: 100000000 | G206: 1000 | H206: 1 | I206: 1 | J206: 1 | K206: =J206*I206*H206*G206*F206*E206*D206*C206*B206 -> 5.05e+43 | L206: =MATCH(K206, 보스체력!#REF!, 1) -> #REF! | AC206: 205 | AD206: =INT(AC206/5)+1 -> 42 | AE206: {=INDEX(X:X, AD206+1)*AC206} -> 861000
A207: 206 | B207: 595000000 | C207: 100000000 | D207: 100000000 | E207: 100000000 | F207: 100000000 | G207: 1000 | H207: 1 | I207: 1 | J207: 1 | K207: =J207*I207*H207*G207*F207*E207*D207*C207*B207 -> 5.95e+43 | L207: =MATCH(K207, 보스체력!#REF!, 1) -> #REF! | AC207: 206 | AD207: =INT(AC207/5)+1 -> 42 | AE207: {=INDEX(X:X, AD207+1)*AC207} -> 865200
...

Sheet 보스데미지
A1: 스테이지 | B1: 1번값 | C1: 2번값 | D1: 3번값 | E1: 4번값 | F1: 5번값 | G1: 6번값 | H1: 7번값 | I1: 8번값 | J1: 9번값
A2: 1 | B2: 1 | C2: 1 | D2: 1 | E2: 1 | F2: 1 | G2: 1 | H2: 1 | I2: 1 | J2: 1
A3: 2 | B3: 2 | C3: 1 | D3: 1 | E3: 1 | F3: 1 | G3: 1 | H3: 1 | I3: 1 | J3: 1
A4: 3 | B4: 3 | C4: 1 | D4: 1 | E4: 1 | F4: 1 | G4: 1 | H4: 1 | I4: 1 | J4: 1
A5: 4 | B5: 4 | C5: 1 | D5: 1 | E5: 1 | F5: 1 | G5: 1 | H5: 1 | I5: 1 | J5: 1
A6: 5 | B6: 8 | C6: 1 | D6: 1 | E6: 1 | F6: 1 | G6: 1 | H6: 1 | I6: 1 | J6: 1
A7: 6 | B7: 11 | C7: 1 | D7: 1 | E7: 1 | F7: 1 | G7: 1 | H7: 1 | I7: 1 | J7: 1
A8: 7 | B8: 13 | C8: 1 | D8: 1 | E8: 1 | F8: 1 | G8: 1 | H8: 1 | I8: 1 | J8: 1
A9: 8 | B9: 15 | C9: 1 | D9: 1 | E9: 1 | F9: 1 | G9: 1 | H9: 1 | I9: 1 | J9: 1
A10: 9 | B10: 17 | C10: 1 | D10: 1 | E10: 1 | F10: 1 | G10: 1 | H10: 1 | I10: 1 | J10: 1
A11: 10 | B11: 19 | C11: 1 | D11: 1 | E11: 1 | F11: 1 | G11: 1 | H11: 1 | I11: 1 | J11: 1
A12: 11 | B12: 21 | C12: 1 | D12: 1 | E12: 1 | F12: 1 | G12: 1 | H12: 1 | I12: 1 | J12: 1
A13: 12 | B13: 23 | C13: 1 | D13: 1 | E13: 1 | F13: 1 | G13: 1 | H13: 1 | I13: 1 | J13: 1
... A1501: 1500 | B1501: 606205622 | C1501: 100000000 | D1501: 100000000 | E1501: 100000000 | F1501: 100000000 | G1501: 100000000 | H1501: 100000000 | I1501: 100000000 | J1501: 100000000

Sheet 능력치
H2: 정수 | J2: 강화횟수 | K2: 공격력 | L2: 근력 | M2: 생명력 | N2: 체력 | O2: 누적금화 | AA2: ID | AB2: 나무이름 | AC2: 승급시 상승능력치 | AD2: 승급시 소모비용1 | AE2: 승급시 소모비용2
I3: 3 | J3: 19800 | K3: {=INDIRECT("'[상승값.xlsx]상승'!B" & (J3+1))} -> #REF! | L3: {=INDIRECT("'[상승값.xlsx]상승'!C" & (J3+1))} -> #REF! | M3: {=INDIRECT("'[상승값.xlsx]상승'!B" & (J3+1))} -> #REF! | N3: {=INDIRECT("'[상승값.xlsx]상승'!C" & (J3+1))} -> #REF! | O3: {=INDIRECT("'[상승값.xlsx]상승'!E" & (J3+1))} -> #REF! | AA3: 0 | AB3: 0 | AC3: 0 | AD3: 0 | AE3: 0 | AF3: 0 | AI3: ID | AJ3: 나무이름 | AK3: 성장최대치 | AL3: 퍼센트 증가량 | AM3: 가격 증가량 | AN3: 승급시 상승능력치 | AO3: 승급시 소모비용1 | AP3: 승급시 소모비용2
F4: "'[상승값.xlsx]상승'! | I4: 스킬강횟수 | J4: {=MATCH(TRUE, INDEX(INT(스킬!B1:B130/J3)<>0, 0), 0)} -> 126 | AA4: 1 | AB4: 씨앗 | AC4: 150 | AD4: 500 | AE4: =AE3+AD4 -> 500 | AF4: 50 | AI4: 1 | AJ4: 씨앗 | AK4: 50 | AL4: 1 | AM4: 1 | AN4: 150 | AO4: 500 | AP4: 5
H5: 스킬 | J5: 0 | K5: 1 | L5: 2 | M5: 3 | N5: 4 | O5: 누적금화 | AA5: 2 | AB5: 뿌리 | AC5: 150 | AD5: 1000 | AE5: =AE4+AD5 -> 1500 | AF5: 150 | AI5: 2 | AJ5: 뿌리 | AK5: 150 | AL5: 1 | AM5: 2 | AN5: 150 | AO5: 1000 | AP5: 10
J6: =VLOOKUP(J5, INDIRECT("스킬!H" & ($J4-5) & ":L" & ($J4-1)), 3, FALSE) -> 14400 | K6: =VLOOKUP(K5, INDIRECT("스킬!H" & ($J4-5) & ":L" & ($J4-1)), 3, FALSE) -> 12000 | L6: =VLOOKUP(L5, INDIRECT("스킬!H" & ($J4-5) & ":L" & ($J4-1)), 3, FALSE) -> 10800 | M6: =VLOOKUP(M5, INDIRECT("스킬!H" & ($J4-5) & ":L" & ($J4-1)), 3, FALSE) -> 9600 | N6: =VLOOKUP(N5, INDIRECT("스킬!H" & ($J4-5) & ":L" & ($J4-1)), 3, FALSE) -> 600 | O6: =VLOOKUP(J4-1, 스킬!A$2:L$126, 12, FALSE) -> 21621336961 | AA6: 3 | AB6: 새싹 | AC6: 250 | AD6: 1500 | AE6: =AE5+AD6 -> 3000 | AF6: 250 | AI6: 3 | AJ6: 새싹 | AK6: 250 | AL6: 2 | AM6: 3 | AN6: 250 | AO6: 1500 | AP6: 15
H7: 초월 | J7: 강화횟수 | K7: 공격력 | L7: 생명력 | O7: 누적 초월석 | AA7: 4 | AB7: 잎새 | AC7: 250 | AD7: 2000 | AE7: =AE6+AD7 -> 5000 | AF7: 350 | AI7: 4 | AJ7: 잎새 | AK7: 350 | AL7: 2 | AM7: 4 | AN7: 250 | AO7: 2000 | AP7: 20
I8: 7 | J8: 479 | K8: {=INDIRECT("'[상승값.xlsx]상승'!G" & (J8+1))} -> #REF! | L8: {=INDIRECT("'[상승값.xlsx]상승'!G" & (J8+1))} -> #REF! | O8: {=INDIRECT("'[상승값.xlsx]상승'!I" & (J8+1))} -> #REF! | AA8: 5 | AB8: 가지 | AC8: 400 | AD8: 2500 | AE8: =AE7+AD8 -> 7500 | AF8: 450 | AI8: 5 | AJ8: 가지 | AK8: 450 | AL8: 3 | AM8: 5 | AN8: 400 | AO8: 2500 | AP8: 25
AA9: 6 | AB9: 묘목 | AC9: 400 | AD9: 3000 | AE9: =AE8+AD9 -> 10500 | AF9: 550 | AI9: 6 | AJ9: 묘목 | AK9: 550 | AL9: 3 | AM9: 6 | AN9: 400 | AO9: 3000 | AP9: 30
AA10: 7 | AB10: 견목 | AC10: 600 | AD10: 3500 | AE10: =AE9+AD10 -> 14000 | AF10: 650 | AI10: 7 | AJ10: 견목 | AK10: 650 | AL10: 4 | AM10: 7 | AN10: 600 | AO10: 3500 | AP10: 35
H11: 룬 | J11: 강화 레벨 | K11: 공격력 | L11: 생명 | M11: 금화 | N11: 근력 | O11: 체력 | P11: 강화 | Q11: 경험 | R11: 누적룬 | AA11: 8 | AB11: 성목 | AC11: 600 | AD11: 4000 | AE11: =AE10+AD11 -> 18000 | AF11: 750 | AI11: 8 | AJ11: 성목 | AK11: 750 | AL11: 4 | AM11: 8 | AN11: 600 | AO11: 4000 | AP11: 40
I12: 11 | J12: 61 | K12: {=INDIRECT("'[상승값.xlsx]상승'!I" & (J12+1))} -> #REF! | L12: {=INDIRECT("'[상승값.xlsx]상승'!I" & (J12+1))} -> #REF! | M12: {=INDIRECT("'[상승값.xlsx]상승'!k" & (J12+1))} -> #REF! | N12: {=INDIRECT("'[상승값.xlsx]상승'!J" & (J12+1))} -> #REF! | O12: {=INDIRECT("'[상승값.xlsx]상승'!J" & (J12+1))} -> #REF! | P12: {=INDIRECT("'[상승값.xlsx]상승'!k" & (J12+1))} -> #REF! | Q12: {=INDIRECT("'[상승값.xlsx]상승'!k" & (J12+1))} -> #REF! | R12: {=INDIRECT("'[상승값.xlsx]상승'!M" & (J12*7+1))} -> #REF! | AA12: 9 | AB12: 거목 | AC12: 900 | AD12: 4500 | AE12: =AE11+AD12 -> 22500 | AF12: 850 | AI12: 9 | AJ12: 거목 | AK12: 850 | AL12: 5 | AM12: 9 | AN12: 900 | AO12: 4500 | AP12: 45
AA13: 10 | AB13: 신목 | AC13: 900 | AD13: 5000 | AE13: =AE12+AD13 -> 27500 | AF13: 950 | AI13: 10 | AJ13: 신목 | AK13: 950 | AL13: 5 | AM13: 10 | AN13: 900 | AO13: 5000 | AP13: 50
A14: I | H14: 나무 | J14: 등급 | K14: 강화횟수 | L14: 공격력 | M14: 생명력 | N14: 몬 피해량 | O14: 보 피해량 | R14: 누적 소모 | S14: 승급 누적 | T14: 총 소모 | AA14: 11 | AB14: 영목 | AC14: 1350 | AD14: 5500 | AE14: =AE13+AD14 -> 33000 | AF14: 1050 | AI14: 11 | AJ14: 영목 | AK14: 1050 | AL14: 6 | AM14: 11 | AN14: 1350 | AO14: 5500 | AP14: 55
I15: 14 | J15: 6 | K15: =VLOOKUP(J15-1,AA3:AF26, 6, FALSE) -> 450 | L15: {=INDIRECT("'[상승값.xlsx]상승'!N" & (K15+2))} -> #REF! | M15: {=INDIRECT("'[상승값.xlsx]상승'!N" & (K15+2))} -> #REF! | N15: {=INDIRECT("'[상승값.xlsx]상승'!N" & (K15+2))} -> #REF! | O15: {=INDIRECT("'[상승값.xlsx]상승'!N" & (K15+2))} -> #REF! | R15: {=4*INDIRECT("'[상승값.xlsx]상승'!O" & (K15+1))} -> #REF! | S15: =VLOOKUP(J15,AA3:AE23, 5, FALSE) -> 10500 | T15: =S15+R15 -> #REF! | AA15: 12 | AB15: 천목 | AC15: 1350 | AD15: 6000 | AE15: =AE14+AD15 -> 39000 | AF15: 1150 | AI15: 12 | AJ15: 천목 | AK15: 1150 | AL15: 6 | AM15: 12 | AN15: 1350 | AO15: 6000 | AP15: 60
AA16: 13 | AB16: 태초목 | AC16: 2000 | AD16: 6500 | AE16: =AE15+AD16 -> 45500 | AF16: 1250 | AI16: 13 | AJ16: 태초목 | AK16: 1250 | AL16: 7 | AM16: 13 | AN16: 2000 | AO16: 6500 | AP16: 65
G17: 능력치로 | H17: 나무 승급 | K17: 나무 이름 | L17: 승급 공격 | M17: 승급생명 | AA17: 14 | AB17: 창조목 | AC17: 2000 | AD17: 7000 | AE17: =AE16+AD17 -> 52500 | AF17: 1350 | AI17: 14 | AJ17: 창조목 | AK17: 1350 | AL17: 7 | AM17: 14 | AN17: 2000 | AO17: 7000 | AP17: 70
K18: =VLOOKUP(J15,AA4:AE24, 2, FALSE) -> 묘목 | L18: =VLOOKUP(J15,AA3:AE23, 3, FALSE) -> 400 | M18: =VLOOKUP(J15-1,AA3:AE23, 3, FALSE) -> 400 | AA18: 15 | AB18: 수호목 | AC18: 3000 | AD18: 7500 | AE18: =AE17+AD18 -> 60000 | AF18: 1450 | AI18: 15 | AJ18: 수호목 | AK18: 1450 | AL18: 8 | AM18: 15 | AN18: 3000 | AO18: 7500 | AP18: 75
AA19: 16 | AB19: 세계목 | AC19: 3000 | AD19: 8000 | AE19: =AE18+AD19 -> 68000 | AF19: 1550 | AI19: 16 | AJ19: 세계목 | AK19: 1550 | AL19: 8 | AM19: 16 | AN19: 3000 | AO19: 8000 | AP19: 80
H20: 무기 | J20: 최고 무기 | K20: 강화횟수 | L20: 무기장착 | M20: 보유공격 | N20: 보유근력 | AA20: 17 | AB20: 세계수 | AC20: 4500 | AD20: 8500 | AE20: =AE19+AD20 -> 76500 | AF20: 1650 | AI20: 17 | AJ20: 세계수 | AK20: 1650 | AL20: 9 | AM20: 17 | AN20: 4500 | AO20: 8500 | AP20: 85
G21: 능력치로 | J21: 전설3 | K21: 200 | L21: =VLOOKUP(J21, J59:T83, 9, FALSE) -> 9400 | M21: =S84 -> 23705 | N21: =T84 -> 23705 | AA21: 18 | AB21: 신화수 | AC21: 4500 | AD21: 9000 | AE21: =AE20+AD21 -> 85500 | AI21: 18 | AJ21: 신화수 | AK21: 1750 | AL21: 9 | AM21: 18 | AN21: 4500 | AO21: 9000 | AP21: 90
J22: =VLOOKUP(J21, J59:T83, 2, FALSE) -> 19 | AA22: 19 | AB22: 무한수 | AC22: 7000 | AD22: 9500 | AE22: =AE21+AD22 -> 95000 | AF22: 1850 | AI22: 19 | AJ22: 무한수 | AK22: 1850 | AL22: 10 | AM22: 19 | AN22: 7000 | AO22: 9500 | AP22: 95
AA23: 20 | AB23: 영겁수 | AC23: 7000 | AD23: 10000 | AE23: =AE22+AD23 -> 105000 | AF23: 1950 | AI23: 20 | AJ23: 영겁수 | AK23: 1950 | AL23: 10 | AM23: 20 | AN23: 7000 | AO23: 10000 | AP23: 100
H24: 위인 | K24: 일반 | N24: 고려 | Q24: 조선 | T24: 근대 | AA24: 21 | AB24: - | AC24: 0 | AD24: 50000 | AE24: =AE23+AD24 -> 155000 | AF24: 0 | AI24: 21 | AJ24: - | AK24: 0 | AL24: 0 | AM24: 0 | AN24: 0 | AO24: 50000 | AP24: 50000
I25: 24 | J25: 공격력 | K25: =O92 -> 1300 | M25: 공격력 | N25: =O97 -> 350 | P25: 공격력 | Q25: =O103 -> 160 | S25: 공격력 | T25: =O109 -> 2100
J26: 생명 | K26: =O93 -> 1600 | M26: 생명 | N26: =O98 -> 140 | P26: 생명 | Q26: =O104 -> 160 | S26: 생명 | T26: =O110 -> 2100
J27: 치명 | K27: =O94 -> 13 | M27: 치명 | N27: =O100 -> 20 | P27: 치명 | Q27: =O106 -> 35
H29: 유물 | K29: 고려 | M29: =VLOOKUP(K30, I129:R139, 9, FALSE) -> 200 | O29: 조선 | S29: 근대
J30: 공격 | K30: 7강 | L30: =K140 -> 270 | M30: =VLOOKUP(K30, I129:R139, 9, FALSE) -> 200 | N30: 공격 | O30: 7강 | P30: =M140 -> 270 | Q30: =VLOOKUP(O30, I129:R139, 9, FALSE) -> 200 | R30: 공격 | S30: 0강 | T30: =O140 -> 0 | U30: =VLOOKUP(S30, I129:R139, 9, FALSE) -> 1
J31: 생명령 | K31: 7강 | L31: =L140 -> 270 | M31: =VLOOKUP(K31, I129:R139, 9, FALSE) -> 200 | N31: 생명령 | O31: 7강 | P31: =N140 -> 270 | Q31: =VLOOKUP(O31, I129:R139, 9, FALSE) -> 200 | R31: 생명령 | S31: 0강 | T31: =P140 -> 0 | U31: =VLOOKUP(S31, I129:R139, 9, FALSE) -> 1
K32: 총 공격력 | L32: =L30*M30 -> 54000 | O32: 총 공격력 | P32: =P30*Q30 -> 54000 | S32: 총 공격력 | T32: =T30*U30 -> 0
K34: =VLOOKUP(K30, I129:R139, 10, FALSE) -> 7 | N34: =VLOOKUP(O30, I129:R139, 10, FALSE) -> 7 | Q34: =VLOOKUP(S30, I129:R139, 10, FALSE) -> 0
K35: =VLOOKUP(K31, I129:R139, 10, FALSE) -> 7 | N35: =VLOOKUP(O31, I129:R139, 10, FALSE) -> 7 | Q35: =VLOOKUP(S31, I129:R139, 10, FALSE) -> 0
H36: 연구 | J36: 선택 | K36: 공격력 | L36: 생명력 | M36: 보유공증 | N36: 보유근증 | O36: 보유생증 | P36: 보유방증 | Z36: 중세
J37: 고+중 | K37: =HLOOKUP(J37, K150:M159, 2, FALSE) -> 1000 | L37: =HLOOKUP(J37, K150:M159, 3, FALSE) -> 1000 | M37: =HLOOKUP(J37, K150:M159, 5, FALSE) -> 660 | N37: =HLOOKUP(J37, K150:M159, 6, FALSE) -> 360 | O37: =HLOOKUP(J37, K150:M159, 7, FALSE) -> 660 | P37: =HLOOKUP(J37, K150:M159, 8, FALSE) -> 360 | Z37: 중세+고대
I40: 135 | J40: k | K40: l | L40: m | M40: n | N40: o | O40: p
G41: 돌아가기 | H41: 어빌 | J41: 선택 | K41: 능력치 | L41: 총 어빌 | M41: =N46*N50 -> 71236800 | Q41: 1 | R41: 2 | S41: 3 | T41: 4 | U41: 5 | V41: 6 | W41: 7 | X41: 8 | Y41: 9
H42: 1 | I42: 표류자 | J42: 신화 | K42: =VLOOKUP(J42, 능력치!P$42:Y$47, 2, FALSE) -> 150 | L42: 6 | M42: =L42*K42 -> 900 | P42: 일반 | Q42: 8 | R42: 20 | S42: 30 | T42: 40 | U42: 60 | V42: 10 | W42: 14 | X42: 20 | Y42: 30
H43: 2 | I43: 무사 | J43: 일반 | K43: =VLOOKUP(J43, 능력치!P$42:Y$47, H43+1, FALSE) -> 20 | L43: 6 | M43: =L43*K43 -> 120 | P43: 고급 | Q43: 16 | R43: 30 | S43: 40 | T43: 60 | U43: 100 | V43: 14 | W43: 20 | X43: 30 | Y43: 40
H44: 3 | I44: 검객 | J44: 신화 | K44: =VLOOKUP(J44, 능력치!P$42:Y$47, H44+1, FALSE) -> 370 | L44: 6 | M44: =L44*K44 -> 2220 | P44: 희귀 | Q44: 24 | R44: 40 | S44: 60 | T44: 80 | U44: 140 | V44: 20 | W44: 30 | X44: 40 | Y44: 50
H45: 4 | I45: 투사 | J45: 신화 | K45: =VLOOKUP(J45, 능력치!P$42:Y$47, H45+1, FALSE) -> 570 | L45: 6 | M45: =L45*K45 -> 3420 | P45: 영웅 | Q45: 40 | R45: 70 | S45: 100 | T45: 160 | U45: 220 | V45: 30 | W45: 40 | X45: 50 | Y45: 70
...

Sheet 계산
E4: 무42D237킵 | L4: =J3-J6 -> 0
G5: 12240 | H5: 5820 | I5: =H5+G5 -> 18060
C6: 이동 | M6: 정수공x 2 x 룬공/100 *어빌
C7: 공격정수 | D7: OffenseEssence1 | E7: =IFERROR(VLOOKUP(D7, INDIRECT("'[" & $E$4 & ".xlsx]Sheet1'!$A:$C"), 3, FALSE), "찾을 수 없음") -> 찾을 수 없음 | F7: =IF(E7="찾을 수 없음", 100, E7) -> 100 | G7: =F7 -> 100 | J7: 정수 공 | K7: =(G7*2) -> 200 | M7: (정수 x 2)
C8: 공격근력 | D8: OffenseEssence2 | E8: =IFERROR(VLOOKUP(D8, INDIRECT("'[" & $E$4 & ".xlsx]Sheet1'!$A:$C"), 3, FALSE), "찾을 수 없음") -> 찾을 수 없음 | F8: =IF(E8="찾을 수 없음", 100, E8) -> 100 | G8: =F8 -> 100 | J8: 룬공 | K8: =(G12/100) -> 1 | M8: (룬 공 /100)
C9: 초월 공격력 | D9: OffenseGrowth2_1 | E9: =IFERROR(VLOOKUP(D9, INDIRECT("'[" & $E$4 & ".xlsx]Sheet1'!$A:$C"), 3, FALSE), "찾을 수 없음") -> 찾을 수 없음 | F9: =IF(E9="찾을 수 없음", 100, E9) -> 100 | G9: =F9 -> 100 | J9: 어빌공/증폭 | K9: =(G10*G11/10000) -> 7123.68 | M9: (어빌 x 어빌 공근 증폭)/10000
C10: 어빌 | D10: OffenseGrowth3_1 | E10: =IFERROR(VLOOKUP(D10, INDIRECT("'[" & $E$4 & ".xlsx]Sheet1'!$A:$C"), 3, FALSE), "찾을 수 없음") -> 찾을 수 없음 | F10: =IF(E10="찾을 수 없음", 100, E10) -> 100 | G10: 12240 | J10: 연구공/증폭 | K10: =(G31*G32/10000) -> 13 | M10: (연구 공근 x연구공근증폭 ) /10000
C11: 어빌증폭 | D11: OffenseGrowth3_2 | E11: =IFERROR(VLOOKUP(D11, INDIRECT("'[" & $E$4 & ".xlsx]Sheet1'!$A:$C"), 3, FALSE), "찾을 수 없음") -> 찾을 수 없음 | F11: =IF(E11="찾을 수 없음", 100, E11) -> 100 | G11: 5820 | J11: 나무공 | K11: =G14/1000 -> 0.1 | M11: 나무 공격력 /1000
C12: 룬 공격력 | D12: OffenseGrowth4_1 | E12: =IFERROR(VLOOKUP(D12, INDIRECT("'[" & $E$4 & ".xlsx]Sheet1'!$A:$C"), 3, FALSE), "찾을 수 없음") -> 찾을 수 없음 | F12: =IF(E12="찾을 수 없음", 100, E12) -> 100 | G12: =F12 -> 100 | J12: 나무승급공 | K12: =G15/100 -> 1 | L12: =K7*K8*K9*K10*K11*K12 -> 1852156.8 | M12: 나무 승급 공격력/100
C13: 룬 근력 | D13: OffenseGrowth4_2 | E13: =IFERROR(VLOOKUP(D13, INDIRECT("'[" & $E$4 & ".xlsx]Sheet1'!$A:$C"), 3, FALSE), "찾을 수 없음") -> 찾을 수 없음 | F13: =IF(E13="찾을 수 없음", 100, E13) -> 100 | G13: =F13 -> 100 | L13: =L12+K14 -> 1852256.8
C14: 나무 | D14: OffenseGrowth5_1 | E14: =IFERROR(VLOOKUP(D14, INDIRECT("'[" & $E$4 & ".xlsx]Sheet1'!$A:$C"), 3, FALSE), "찾을 수 없음") -> 찾을 수 없음 | F14: =IF(E14="찾을 수 없음", 100, E14) -> 100 | G14: =F14 -> 100 | J14: 정수 근+룬 근 | K14: =(G8*G13/100) -> 100 | L14: =K7*K8*K9*K10*K11*K12+K14 -> 1852256.8
C15: 나무진화 | D15: OffenseGrowth5_2 | E15: =IFERROR(VLOOKUP(D15, INDIRECT("'[" & $E$4 & ".xlsx]Sheet1'!$A:$C"), 3, FALSE), "찾을 수 없음") -> 찾을 수 없음 | F15: =IF(E15="찾을 수 없음", 100, E15) -> 100 | G15: =F15 -> 100
C16: 장비장착 | D16: OffenseEquipmentEquip | E16: =IFERROR(VLOOKUP(D16, INDIRECT("'[" & $E$4 & ".xlsx]Sheet1'!$A:$C"), 3, FALSE), "찾을 수 없음") -> 찾을 수 없음 | F16: =IF(E16="찾을 수 없음", 100, E16) -> 100 | G16: =F16 -> 100 | H16: 1 | M16: 정수 근력
C17: 장비보유 | D17: Offense1EquipmentHave | E17: =IFERROR(VLOOKUP(D17, INDIRECT("'[" & $E$4 & ".xlsx]Sheet1'!$A:$C"), 3, FALSE), "찾을 수 없음") -> 찾을 수 없음 | F17: =IF(E17="찾을 수 없음", 100, E17) -> 100 | G17: =F17 -> 100 | H17: 2 | M17: 룬 근 /100
C18: 장비보유근력 | D18: Offense2EquipmentHave | E18: =IFERROR(VLOOKUP(D18, INDIRECT("'[" & $E$4 & ".xlsx]Sheet1'!$A:$C"), 3, FALSE), "찾을 수 없음") -> 찾을 수 없음 | F18: =IF(E18="찾을 수 없음", 100, E18) -> 100 | G18: =F18 -> 100 | H18: 3 | J18: 장비 공 | K18: =(G16+(G17*G37/100)+(G38*G18/100/2))/100 -> 10.9 | M18: (장비 공격력 +
C19: 고려영웅 | D19: OffenseHero2 | E19: =IFERROR(VLOOKUP(D19, INDIRECT("'[" & $E$4 & ".xlsx]Sheet1'!$A:$C"), 3, FALSE), "찾을 수 없음") -> 찾을 수 없음 | F19: =IF(E19="찾을 수 없음", 100, E19) -> 100 | G19: =F19 -> 100 | J19: 초월 공 | K19: =G9/100 -> 1 | M19: (무기보유 공격력 * 장비증폭)/100 +
C20: 조선영웅 | D20: OffenseHero3 | E20: =IFERROR(VLOOKUP(D20, INDIRECT("'[" & $E$4 & ".xlsx]Sheet1'!$A:$C"), 3, FALSE), "찾을 수 없음") -> 찾을 수 없음 | F20: =IF(E20="찾을 수 없음", 100, E20) -> 100 | G20: =F20 -> 100 | J20: 위인 공 | K20: =G19*G20*G21/100/100/100 -> 1 | M20: (무기 보유 근력 *장비증폭/100/2) )/100
C21: 근현대영웅 | D21: OffenseHero4 | E21: =IFERROR(VLOOKUP(D21, INDIRECT("'[" & $E$4 & ".xlsx]Sheet1'!$A:$C"), 3, FALSE), "찾을 수 없음") -> 찾을 수 없음 | F21: =IF(E21="찾을 수 없음", 100, E21) -> 100 | G21: 100 | J21: 승급 공 | K21: =G22/100 -> 1
C22: 승급 | D22: OffenseCharacterUp | E22: =IFERROR(VLOOKUP(D22, INDIRECT("'[" & $E$4 & ".xlsx]Sheet1'!$A:$C"), 3, FALSE), "찾을 수 없음") -> 찾을 수 없음 | F22: =IF(E22="찾을 수 없음", 100, E22) -> 100 | G22: =F22 -> 100 | J22: 유물 고려 공 | K22: =G24*G27/10000*G25*G28/10000*G26*G29/10000 -> 1 | M22: 초월 공격력 /100 | O22: d | W22: // 기본 스킬 데미지
S23: 6.1747438e+27 | W23: // 안쓸떄 200 쓸떄 스킬뎀지 / 100 *
D24: OffenseTreasure1 | E24: =IFERROR(VLOOKUP(D24, INDIRECT("'[" & $E$4 & ".xlsx]Sheet1'!$A:$C"), 3, FALSE), "찾을 수 없음") -> 찾을 수 없음 | F24: =IF(E24="찾을 수 없음", 100, E24) -> 100 | G24: =F24 -> 100 | M24: 고려위인공격력 /100 | S24: 1.1114539e+30 | T24: =S24/S23 -> 180 | W24: // 치명타 데미지 x 치명타증폭 /100 +100/ 100 *
D25: OffenseTreasure2 | E25: =IFERROR(VLOOKUP(D25, INDIRECT("'[" & $E$4 & ".xlsx]Sheet1'!$A:$C"), 3, FALSE), "찾을 수 없음") -> 찾을 수 없음 | F25: =IF(E25="찾을 수 없음", 100, E25) -> 100 | G25: =F25 -> 100 | M25: 조선위인공격력 /100 | W25: // 숙련도 슈바니 150~200 | Z25: / 100 *
D26: OffenseTreasure3 | E26: =IFERROR(VLOOKUP(D26, INDIRECT("'[" & $E$4 & ".xlsx]Sheet1'!$A:$C"), 3, FALSE), "찾을 수 없음") -> 찾을 수 없음 | F26: =IF(E26="찾을 수 없음", 100, E26) -> 100 | G26: =F26 -> 100 | K26: =K18*K19*K20*K21*K22 -> 10.9 | M26: 근대위인공격력 /100 | W26: // 스킬 버프 | Y26: 스킬쓸떄는 100 안쓸떄는 625 | AB26: / 100 *
C27: 위인 | D27: OffenseTreasureMix1 | E27: =IFERROR(VLOOKUP(D27, INDIRECT("'[" & $E$4 & ".xlsx]Sheet1'!$A:$C"), 3, FALSE), "찾을 수 없음") -> 찾을 수 없음 | F27: =IF(E27="찾을 수 없음", 100, E27) -> 100 | G27: =F27 -> 100 | W27: // 광고 버프 3
C28: 위인 | D28: OffenseTreasureMix2 | E28: =IFERROR(VLOOKUP(D28, INDIRECT("'[" & $E$4 & ".xlsx]Sheet1'!$A:$C"), 3, FALSE), "찾을 수 없음") -> 찾을 수 없음 | F28: =IF(E28="찾을 수 없음", 100, E28) -> 100 | G28: =F28 -> 100 | J28: 총합 offenseCalcul * | K28: =L14*K26 -> 20189599 | M28: 캐릭터승급 /100
C29: 위인 | D29: OffenseTreasureMix3 | E29: =IFERROR(VLOOKUP(D29, INDIRECT("'[" & $E$4 & ".xlsx]Sheet1'!$A:$C"), 3, FALSE), "찾을 수 없음") -> 찾을 수 없음 | F29: =IF(E29="찾을 수 없음", 100, E29) -> 100 | G29: =F29 -> 100 | M29: 고려유물공격력 x 고려유물공격력증폭 /10000 | W29: // 치명타 적용 여부 | Y29: 1
M30: 조선 x 조선증폭 /10000
C31: 연구 | D31: OffenseResearch1 | E31: =IFERROR(VLOOKUP(D31, INDIRECT("'[" & $E$4 & ".xlsx]Sheet1'!$A:$C"), 3, FALSE), "찾을 수 없음") -> 찾을 수 없음 | F31: =IF(E31="찾을 수 없음", 100, E31) -> 100 | G31: 1300 | J31: 892 | K31: 4.4485842e+33 | L31: =K28/K31 -> 4.5384325e-27 | M31: 근대 x 근대 /10000
C32: 연구증폭 | D32: OffenseResearch2 | E32: =IFERROR(VLOOKUP(D32, INDIRECT("'[" & $E$4 & ".xlsx]Sheet1'!$A:$C"), 3, FALSE), "찾을 수 없음") -> 찾을 수 없음 | F32: =IF(E32="찾을 수 없음", 100, E32) -> 100 | G32: =F32 -> 100 | J32: 893 | K32: 4.8530006e+33
D33: 신규 | K33: 5.0552088e+33 | M33: 능력치로
D34: 항목 | G34: 값 | J34: damageCalcul =
C35: critical1_Damage | D35: critical1_Damage | E35: =IFERROR(VLOOKUP(D35, INDIRECT("'[" & $E$4 & ".xlsx]Sheet1'!$A:$C"), 3, FALSE), "찾을 수 없음") -> 찾을 수 없음 | F35: =IF(E35="찾을 수 없음", 100, E35) -> 100 | G35: =F35 -> 100 | I35: ㅇ | J35: offenseCalcul * | M35: =K28 -> 20189599 | P35: 기본
D36: DungeonPowerUp2 | E36: =IFERROR(VLOOKUP(D36, INDIRECT("'[" & $E$4 & ".xlsx]Sheet1'!$A:$C"), 3, FALSE), "찾을 수 없음") -> 찾을 수 없음 | F36: =IF(E36="찾을 수 없음", 100, E36) -> 100 | G36: =F36 -> 100 | I36: ㅌ | J36: NomalAndBossDamageCalcul() | L36: 315 | M36: 1350 | O36: 1350 | P36: 1550 | Q36: / 1000 *
D37: Offense1EquipmentHaveUp | E37: 760 | F37: =IF(E37="찾을 수 없음", 100, E37) -> 760 | G37: =F37 -> 760 | I37: ㅌ | J37: HeroPlaceDamageCalcul() | L37: 445 | M37: 1 | O37: 보스전100 | Q37: / 100 *
D38: Offense2EquipmentHaveUp | E38: 460 | F38: =IF(E38="찾을 수 없음", 100, E38) -> 460 | G38: =F38 -> 460 | I38: ㅇ | J38: awakeDamage | L38: =L37/L36 -> 1.4126984 | M38: =IFERROR(VLOOKUP(J38, INDIRECT("'[" & $E$4 & ".xlsx]Sheet1'!$A:$C"), 3, FALSE), "찾을 수 없음") -> 찾을 수 없음 | O38: 2000 | Q38: / 100 *//무기각성
D39: Hp1EquipmentHaveUp | E39: =IFERROR(VLOOKUP(D39, INDIRECT("'[" & $E$4 & ".xlsx]Sheet1'!$A:$C"), 3, FALSE), "찾을 수 없음") -> 찾을 수 없음 | F39: =IF(E39="찾을 수 없음", 100, E39) -> 100 | G39: =F39 -> 100 | I39: ㅇ | J39: awakeDamage2 | M39: =IFERROR(VLOOKUP(J39, INDIRECT("'[" & $E$4 & ".xlsx]Sheet1'!$A:$C"), 3, FALSE), "찾을 수 없음") -> 찾을 수 없음 | O39: 700 | Q39: / 100 *//방어구각성
D40: Hp2EquipmentHaveUp | E40: =IFERROR(VLOOKUP(D40, INDIRECT("'[" & $E$4 & ".xlsx]Sheet1'!$A:$C"), 3, FALSE), "찾을 수 없음") -> 찾을 수 없음 | F40: =IF(E40="찾을 수 없음", 100, E40) -> 100 | G40: =F40 -> 100 | I40: ㅇ | J40: finalDamage | M40: 100 | O40: 100 | Q40: / 100//미확정
A41: 660 | D41: KnockBackGuard | E41: =IFERROR(VLOOKUP(D41, INDIRECT("'[" & $E$4 & ".xlsx]Sheet1'!$A:$C"), 3, FALSE), "찾을 수 없음") -> 찾을 수 없음 | F41: =IF(E41="찾을 수 없음", 100, E41) -> 100 | G41: =F41 -> 100 | J41: / 10; | M41: 0.1 | T41: 최댓값 | U41: 14400 | V41: 12000 | W41: 10800 | X41: 9600 | Y41: 625
A42: 360 | D42: CriticalConfirm | E42: =IFERROR(VLOOKUP(D42, INDIRECT("'[" & $E$4 & ".xlsx]Sheet1'!$A:$C"), 3, FALSE), "찾을 수 없음") -> 찾을 수 없음 | F42: =IF(E42="찾을 수 없음", 100, E42) -> 100 | G42: =F42 -> 100 | K42: 넉백 3.5 | M42: =M35*M36*M37*M38*M39*M40*M41 -> #VALUE! | T42: skillDamage
J44: enemy.GetDamage( | U44: 1 | V44: 2 | W44: 3 | X44: 4 | Y44: 5 | Z44: 평타
...

Sheet Sheet2
H9: 1:12:30:45 | I9: 0:5:15:30 | J9: =H9+I9 -> #VALUE!
J14: 넉백올방어 | N14: 넉백방어1 | P14: 넉백방어3
I15: 78 | J15: 78 | K15: 77 | L15: 78 | N15: 70번 | P15: 75 | R15: 62
O16: ` | R16: 63
N21: 1회방어
N22: 66
F27: 스킬뎀 | G27: 크리티칼고정 | H27: 숙련도 | I27: 스킬버프
E28: 4 | F28: 14400 | H28: 중간값 | I28: 100 | J28: 28 | L28: =I28*F28*E28 -> 5760000 | M28: =L28/$J$36 -> #DIV/0!
E29: 3 | F29: 12000 | I29: 625 | J29: 38 | L29: =I28*F29*E29 -> 3600000 | M29: =L29/$J$36 -> #DIV/0!
E30: 2 | F30: 10800 | J30: 17 | L30: =I28*F30*E30 -> 2160000 | M30: =L30/$J$36 -> #DIV/0!
E31: 2 | F31: 9600 | L31: =I28*F31*E31 -> 1920000 | M31: =L31/$J$36 -> #DIV/0!
E32: 55 | F32: 200 | L32: =I28*F32*E32*17 -> 18700000 | M32: =L32/$J$36 -> #DIV/0!
E33: =SUM(E28:E32) -> 66 | L33: =38*I29*F32 -> 4750000 | M33: =L33/$J$36 -> #DIV/0!
L34: =SUM(L28:L33) -> 36890000
I35: 이게오른다
F36: 스킬뎀 | G36: 크리티칼고정 | H36: 숙련도 | I36: 스킬버프
E37: 4 | F37: 14400 | H37: 중간값 | I37: 100 | J37: 28
E38: 3 | F38: 12000 | I38: 625 | J38: 38
E39: 2 | F39: 10800 | J39: 17
E40: 2 | F40: 9600
E41: 54 | F41: 200
E42: =SUM(E37:E41) -> 65
F45: 항목 | G45: 값 범위 | H45: 횟수 | I45: 특징
F46: skillDamageCalcul | G46: 200, 9600, 10800, 12000, 14400 | H46: 65 | I46: 200(54), 14400(4), 12000(3), 10800(2), 9600(2)
F47: skillBuffDamage | G47: 100, 625 | H47: 65 | I47: 100(28) → 625(37), 28번째부터 전환

Sheet 스킬
A1: 아이디 | B1: 획득조건 | C1: 스킬가격 | D1: 스킬가격추가 | E1: 스킬가격곱셈 | F1: 스킬레벨 | G1: 스킬단계 | H1: 스킬번호 | J1: 스킬 뎀지 | K1: 번호 | L1: 누적비용 | N1: 아이디 | O1: 스킬번호 | P1: 이름 | Q1: 설명1 | R1: 기본값 | S1: 상승값 | T1: 사거리/지속시간 | U1: 마리수 | V1: 대기시간 | W1: 타격횟수
A2: 1 | B2: 15 | C2: 850 | D2: 1 | E2: 2 | F2: =INT((A2-1)/5)+2 -> 2 | G2: =INT((A2-1)/25)+1 -> 1 | H2: =MOD(A2-1, 5) -> 0 | I2: =_xlfn.TEXTJOIN("", TRUE, TEXT(G2,"0"), TEXT(H2,"0")) -> 10 | J2: =VLOOKUP(I2, O$2:W$26, 4, FALSE)+VLOOKUP(I2, O$2:W$26, 5, FALSE)*(F2-1) -> 660 | L2: 850 | O2: 10 | P2: 폭염참 | Q2: 강력한 한 번의 공격으로 적을 격파하는 스킬. | R2: 600 | S2: 60 | T2: 1.7 | U2: 1 | V2: 7 | W2: 1
A3: 2 | B3: 30 | C3: 3315 | D3: 1 | E3: 2 | F3: =INT((A3-1)/5)+2 -> 2 | G3: =INT((A3-1)/25)+1 -> 1 | H3: =MOD(A3-1, 5) -> 1 | I3: =_xlfn.TEXTJOIN("", TRUE, TEXT(G3,"0"), TEXT(H3,"0")) -> 11 | J3: =VLOOKUP(I3, O$2:W$26, 4, FALSE)+VLOOKUP(I3, O$2:W$26, 5, FALSE)*(F3-1) -> 550 | L3: =C3+L2 -> 4165 | O3: 11 | P3: 대지분쇄 | Q3: 강력한 힘으로 대상을 완전히 파괴하거나 파쇄하는 스킬. | R3: 500 | S3: 50 | T3: 2.5 | U3: 2 | V3: 12 | W3: 1
A4: 3 | B4: 45 | C4: 7757 | D4: 1 | E4: 2 | F4: =INT((A4-1)/5)+2 -> 2 | G4: =INT((A4-1)/25)+1 -> 1 | H4: =MOD(A4-1, 5) -> 2 | I4: =_xlfn.TEXTJOIN("", TRUE, TEXT(G4,"0"), TEXT(H4,"0")) -> 12 | J4: =VLOOKUP(I4, O$2:W$26, 4, FALSE)+VLOOKUP(I4, O$2:W$26, 5, FALSE)*(F4-1) -> 495 | L4: =C4+L3 -> 11922 | O4: 12 | P4: 화룡염탄 | Q4: 불꽃과 열기를 발산하여 지면을 흩뿌리며 폭발적인 염탄을 날리는 스킬. | R4: 450 | S4: 45 | T4: 3 | U4: 3 | V4: 15 | W4: 1
